Workbook

Sheet Language
C1: DB Equipment - Category | J1: BRAND - CALIBRATION
A2: ENGLISH | B2: FRANÇAIS | C2: DEUTSCH | D2: ESPAÑOL | E2: ITALIANO | G2: ENGLISH FIRST 255 | H2: ENGLISH | I2: FRANÇAIS | J2: DEUTSCH | K2: ESPAÑOL | L2: ITALIANO
A3: 1 | B3: 2 | C3: 3 | D3: 4 | E3: 5 | G3: 1 | H3: 2 | I3: 3 | J3: 4 | K3: 5 | L3: 6
G4: EESEEU505B | H4: Includes: - AC400 Clamps - Ride height targets - TIP target - 1 year Premium Free Subscription - CE Conform * Calibration targets and accessories sold separately | I4: - 4 cibles avec griffes universelles AC400 - Jeu de mise à niveau - TIP (Target Imaging Pointer) - 1 an d'abonnement Premium gratuit - Conformité CE * Cibles d'étalonnage et accessoires vendus séparément | J4: - AC400 radklammern - Kit für Fahrzeugniveau messung - TIP (Target Imaging Pointer) - 1 Jahr kostenloses Premium-Abonnement - CE-konform * Kalibriertafeln und Zubehör sind separat erhältlich | K4: - 4 abrazaderas de rueda AC400 - Dianas de altura de conducción a demanda - TIP (puntero de imagen de la diana) - 1 año de suscripción gratuita premium - Cumple com CE * Las dianas de calibración y los accesorios se venden por separado | L4: Includes: - AC400 Clamps - Ride height targets - TIP target - 1 year Premium Free Subscription - CE Conform * Calibration targets and accessories sold separately
G5: EESE900BKEU | H5: Includes: Target Stand, Alignment Fixture, Alignment Fixture w/ Laser, Laser Assembly (2), Alignment Plate, Tape Rule , Tape Rule Stand, Extension Arm (2). Forward Camera Targets (Honda, Acura, Hyundai, Kia, Mazda, Nissan, Infiniti, Audi, Volkswagen, Mercedes-Benz, Toyota, Lexus) | I5: Inclus: Support cible, Dispositif d'alignement, Appareil d'alignement avec laser, Assemblage laser (2), Plaque d'alignement, Règle de bande, Support de règle de bande, Bras d'extension (2). Kit de Caméra Avant (Honda, Acura, Hyundai, Kia, Mazda, Nissan, Infiniti, Audi, Volkswagen, Mercedes-Benz, Toyota, Lexus) | J5: Inkl.: Kalibriertafelbalken, Einstellvorrichtung, Einstellvorrichtung mit Laser, Lasermodule (2), Kalibriertafel, Bandmaß, Halter für Bandmaß, Verlängerungen (2). Frontkameras Kalibriertafeln (Honda, Acura, Hyundai, Kia, Mazda, Nissan, Infiniti, Audi, Volkswagen, Mercedes-Benz, Toyota, Lexus) | K5: Incluye: Soporte de diana, Dispositivo de alineación, Dispositivo de alineación con láser, Conjunto láser (2), Placa de alineación, Cinta métrica, Soporte de la cinta métrica, Brazo de extensión (2). Kit de Diana de Cámara Frontal (Honda, Acura, Hyundai, Kia, Mazda, Nissan, Infiniti, Audi, Volkswagen, Mercedes-Benz, Toyota, Lexus) | L5: Includes: Target Stand, Alignment Fixture, Alignment Fixture w/ Laser, Laser Assembly (2), Alignment Plate, Tape Rule , Tape Rule Stand, Extension Arm (2). Forward Camera Targets (Honda, Acura, Hyundai, Kia, Mazda, Nissan, Infiniti, Audi, Volkswagen, Mercedes-Benz, Toyota, Lexus)
G6: EESE900DXEU | H6: Includes: Target Stand, Alignment Fixture, Alignment Fixture w/ Laser, Laser Assembly (2), Alignment Plate, Tape Rule , Tape Rule Stand, Extension Arm (2), Rear Alignment Plate, Radar Alignment Stand, Front Radar Reflector (3). Forward Camera Targets (Honda, Acura, Hyundai, Kia, Mazda, Nissan, Infiniti, Audi, Volkswagen, Mercedes-Benz, Toyota, Lexus, Subaru, Mitsubishi). Rear Camera Targets (Audi, Volkswagen, Mercedes-Benz). Forward Radar Reflector (Honda, Acura, Mazda, Toyota, Lexus) | I6: Inclus: Support cible, Dispositif d'alignement, Appareil d'alignement avec laser, Assemblage laser (2), Plaque d'alignement, Règle de bande, Support de règle de bande, Bras d'extension (2), Plaque d'alignement arrière, Support d'alignement radar, Réflecteur radar avant (3). Kit de Caméra Avant (Honda, Acura, Hyundai, Kia, Mazda, Nissan, Infiniti, Audi, Volkswagen, Mercedes-Benz, Toyota, Lexus, Subaru, Mitsubishi). Kit de Caméra Arrière (Audi, Volkswagen, Mercedes-Benz). Réflecteurs Radar (Honda, Acura, Mazda, Toyota, Lexus) | J6: Inkl.: Kalibriertafelbalken, Einstellvorrichtung, Einstellvorrichtung mit Laser, Lasermodule (2), Kalibriertafel, Bandmaß, Halter für Bandmaß, Verlängerungen (2), Kalibriertafel hinten, Radareinstellsäule, Radarreflektor vorne (3). Frontkameras Kalibriertafeln (Honda, Acura, Hyundai, Kia, Mazda, Nissan, Infiniti, Audi, Volkswagen, Mercedes-Benz, Toyota, Lexus, Subaru, Mitsubishi). Hintere Kameras Kalibriertafeln (Audi, Volkswagen, Mercedes-Benz). Radarreflektor (Honda, Acura, Mazda, Toyota, Lexus) | K6: Incluye: Soporte de diana, Dispositivo de alineación, Dispositivo de alineación con láser, Conjunto láser (2), Placa de alineación, Cinta métrica, Soporte de la cinta métrica, Brazo de extensión (2), Placa de alineación trasera, Soporte de alineación del radar, Reflector de radar delantero (3). Kit de Diana de Cámara Frontal (Honda, Acura, Hyundai, Kia, Mazda, Nissan, Infiniti, Audi, Volkswagen, Mercedes-Benz, Toyota, Lexus, Subaru, Mitsubishi). Kit de Diana de Cámara Trasera (Audi, Volkswagen, Mercedes-Benz). Reflector de Radar Delantero (Honda, Acura, Mazda, Toyota, Lexus) | L6: Includes: Target Stand, Alignment Fixture, Alignment Fixture w/ Laser, Laser Assembly (2), Alignment Plate, Tape Rule , Tape Rule Stand, Extension Arm (2), Rear Alignment Plate, Radar Alignment Stand, Front Radar Reflector (3). Forward Camera Targets (Honda, Acura, Hyundai, Kia, Mazda, Nissan, Infiniti, Audi, Volkswagen, Mercedes-Benz, Toyota, Lexus, Subaru, Mitsubishi). Rear Camera Targets (Audi, Volkswagen, Mercedes-Benz). Forward Radar Reflector (Honda, Acura, Mazda, Toyota, Lexus)
G7: EAK0362L18A | H7: - Alfa Romeo - Front Camera Target | I7: Alfa Romeo Caméra Avant | J7: Alfa Romeo Frontkameras | K7: Alfa Romeo Cámara Frontal | L7: - Alfa Romeo - Front Camera Target
G8: EAK0362L65A | H8: - Ford - 360 View | I8: Ford Vue 360 | J8: Ford 360-Grad-Ansicht | K8: Ford Vista 360 | L8: - Ford - 360 View
G9: EAK0362L28A | H9: - Honda, Acura - Front Camera Target | I9: Honda, Acura Caméra Avant | J9: Honda, Acura Frontkameras | K9: Honda, Acura Cámara Frontal | L9: - Honda, Acura - Front Camera Target
G10: EAK0362L13A | H10: - Honda - Front Camera Target | I10: Honda Caméra Avant | J10: Honda Frontkameras | K10: Honda Cámara Frontal | L10: - Honda - Front Camera Target
G11: EAK0362L62A | H11: - Honda - Blind Spot Camera | I11: Honda Moniteur d'Angles Morts | J11: Honda Toter-Winkel-Kamera | K11: Honda Cámara de Punto Ciego | L11: - Honda - Blind Spot Camera
G12: EAK0362L29A | H12: - Fiat Hyundai, Kia, Genesis Opel, Vauxhall Peugeot - Front Camera Target | I12: Fiat, Hyundai, Kia, Genesis, Opel, Vauxhall, Peugeot Caméra Avant | J12: Fiat, Hyundai, Kia, Genesis, Opel, Vauxhall, Peugeot Frontkameras | K12: Fiat, Hyundai, Kia, Genesis, Opel, Vauxhall, Peugeot Cámara Frontal | L12: - Fiat Hyundai, Kia, Genesis Opel, Vauxhall Peugeot - Front Camera Target
G13: EAK0362L73A | H13: - Hyundai, Kia, Genesis - 360 View | I13: Hyundai, Kia, Genesis Vue 360 | J13: Hyundai, Kia, Genesis 360-Grad-Ansicht | K13: Hyundai, Kia, Genesis Vista 360 | L13: - Hyundai, Kia, Genesis - 360 View
G14: EAK0362L27A | H14: - Mazda - Front Camera Target | I14: Mazda Caméra Avant | J14: Mazda Frontkameras | K14: Mazda Cámara Frontal | L14: - Mazda - Front Camera Target
G15: EAK0362L33A | H15: - Mazda - Front Camera Target | I15: Mazda Caméra Avant | J15: Mazda Frontkameras | K15: Mazda Cámara Frontal | L15: - Mazda - Front Camera Target
... G20: EAK0362L64A | H20: - 360 View | I20: - 360 View | J20: - 360 Grad | K20: - Vista 360 | L20: - 360 View
G21: EAK0362L30A
G22: EAK0362L26A | H22: - Mercedes-Benz, Nissan, Infiniti - Front Camera Target | I22: Mercedes-Benz, Nissan, Infiniti Caméra Avant | J22: Mercedes-Benz, Nissan, Infiniti Frontkameras | K22: Mercedes-Benz, Nissan, Infiniti Cámara Frontal | L22: - Mercedes-Benz, Nissan, Infiniti - Front Camera Target
G23: EAK0362L20A | H23: - Maserati, Nissan, Infiniti - Front Camera Target | I23: Maserati, Nissan, Infiniti Caméra Avant | J23: Maserati, Nissan, Infiniti Frontkameras | K23: Maserati, Nissan, Infiniti Cámara Frontal | L23: - Maserati, Nissan, Infiniti - Front Camera Target
G24: EAK0388J67A | H24: - Nissan - Park Assist | I24: - Nissan - Park Assist | J24: - Nissan - Park Assist | K24: - Nissan - Park Assist | L24: - Nissan - Park Assist
G25: EAK0362L78A | H25: - Rear Camera | I25: - Caméra arrière | J25: - Rückfahrkamera | K25: - Cámara trasera | L25: - Rear Camera
G26: EAK0388J91A | H26: - Nissan - 360 View | I26: - Nissan - 360 View | J26: - Nissan - 360 Grad | K26: - Nissan - Vista 360 | L26: - Nissan - 360 View
G27: EAK0362L47A | H27: - Mercedes-Benz - Night Vision Target | I27: - Mercedes-Benz - Night vision | J27: - Mercedes-Benz - Night vision | K27: - Mercedes-Benz - Visión nocturna | L27: - Mercedes-Benz - Night Vision Target
G28: EAK0362L45A | H28: - Alfa Romeo, Fiat, Jeep, Seat, Skoda, Nissan, Infiniti, Renault, Audi, Bentley, Porsche, Volkswagen - Front Radar Target | I28: Alfa Romeo, Fiat, Jeep, Seat, Skoda, Nissan, Infiniti, Renault, Audi, Bentley, Porsche, Volkswagen Caméra Avant | J28: Alfa Romeo, Fiat, Jeep, Seat, Skoda, Nissan, Infiniti, Renault, Audi, Bentley, Porsche, Volkswagen Frontkameras | K28: Alfa Romeo, Fiat, Jeep, Seat, Skoda, Nissan, Infiniti, Renault, Audi, Bentley, Porsche, Volkswagen Cámara Frontal | L28: - Alfa Romeo, Fiat, Jeep, Seat, Skoda, Nissan, Infiniti, Renault, Audi, Bentley, Porsche, Volkswagen - Front Radar Target
G29: EAK0370J11A | H29: - Man, Seat, Skoda, Mercedes-Benz, Toyota, Audi, Lamborghini, Volkswagen - Front Radar Target | I29: Man, Seat, Skoda, Mercedes-Benz, Toyota, Audi, Lamborghini, Volkswagen Front Radar Target Nécessite BKT-13 for Tru-Point (EAK0370J34A) Nécessite SM01 for EZ-ADAS (EAK0362L46A) | J29: Man, Seat, Skoda, Mercedes-Benz, Toyota, Audi, Lamborghini, Volkswagen Front Radar Target Erfordert BKT-13 for Tru-Point (EAK0370J34A) Erfordert SM01 for EZ-ADAS (EAK0362L46A) | K29: Man, Seat, Skoda, Mercedes-Benz, Toyota, Audi, Lamborghini, Volkswagen Front Radar Target Requiere BKT-13 for Tru-Point (EAK0370J34A) Requiere SM01 for EZ-ADAS (EAK0362L46A) | L29: - Man, Seat, Skoda, Mercedes-Benz, Toyota, Audi, Lamborghini, Volkswagen - Front Radar Target
G30: EAK0370J30A | H30: - Blind Spot Front Radar | I30: - Blind Spot Front Radar | J30: - Blind Spot Front Radar | K30: - Blind Spot Front Radar | L30: - Blind Spot Front Radar
G31: EAK0362L19A | H31: - Renault, Opel, Vauxhall, Smart - Front Camera Target | I31: Renault, Opel, Vauxhall, Smart Caméra Avant | J31: Renault, Opel, Vauxhall, Smart Frontkameras | K31: Renault, Opel, Vauxhall, Smart Cámara Frontal | L31: - Renault, Opel, Vauxhall, Smart - Front Camera Target
G32: EAK0362L37A | H32: - Subaru - Front Camera Target | I32: Subaru Caméra Avant | J32: Subaru Frontkameras | K32: Subaru Cámara Frontal | L32: - Subaru - Front Camera Target
G33: EAK0362L38A | H33: - Subaru - Front Camera Target | I33: Subaru Caméra Avant | J33: Subaru Frontkameras | K33: Subaru Cámara Frontal | L33: - Subaru - Front Camera Target
... G45: EAK0362L35A | H45: - Rear Camera Target | I45: Kit cible, caméra arrière | J45: Kalibriertafel-Kit hintere Kameras | K45: Kit de objetivos, cámara trasera | L45: - Rear Camera Target
G46: EAA0496L20B
G47: EAK0362L46A | H47: - Bracket | I47: - Supports | J47: - Klammern | K47: - Soportes | L47: - Bracket
G48: EAK0370J23B | H48: - Front Camera Extension Arm - Front Camera | I48: - Bras d'extension de la caméra frontale - Caméra frontale | J48: - Verlängerungsarm der Frontkamera - Frontkamera | K48: - Brazo de extensión de la cámara frontal - Cámara frontal | L48: - Front Camera Extension Arm - Front Camera
G49: EAK0370J22A | H49: - Brackets - Front Camera | I49: - Supports - Caméra frontale | J49: - Klammern - Frontkamera | K49: - Soportes - Cámara frontal | L49: - Brackets - Front Camera
G50: EAK0370J34A | H50: - Support for RAD-04, RAD-05, NV-01, VAG-FL-01 - Front Radar | I50: - Support for RAD-04, RAD-05, NV-01, VAG-FL-01 - Front Radar | J50: - Support for RAD-04, RAD-05, NV-01, VAG-FL-01 - Front Radar | K50: - Support for RAD-04, RAD-05, NV-01, VAG-FL-01 - Front Radar | L50: - Support for RAD-04, RAD-05, NV-01, VAG-FL-01 - Front Radar
G51: EAK0367J20A | H51: - Blind Spot Monitor Target - Radar Blind Spot | I51: - Blind Spot Monitor Target - Radar Blind Spot | J51: - Blind Spot Monitor Target - Radar Blind Spot | K51: - Blind Spot Monitor Target - Radar Blind Spot | L51: - Blind Spot Monitor Target - Radar Blind Spot
G52: EAK0370J57A | H52: - Mazda - Blind Spot Doppler Bracket | I52: - Mazda - Support pour Doppler d'angle mort | J52: - Mazda - Zubehör für toten Winkel Doppler | K52: - Mazda Soporte para doppler de punto ciego | L52: - Mazda - Blind Spot Doppler Bracket
G53: EAK0370J14A | H53: - Front Camera Brackets | I53: - Supports de caméra avant | J53: - Frontkamerahalterungen | K53: - Soportes de cámara frontal | L53: - Front Camera Brackets
G54: EAK0370J36A | H54: - Used with HYU-SC-01 (EAK0362L73A), VAG-SC-01 (EAK0370J05A), VAG-SC-01 (EAK0370J05A) - 360 View | I54: - Utilisé avec HYU-SC-01 (EAK0362L73A), VAG-SC-01 (EAK0370J05A), VAG-SC-01 (EAK0370J05A) - 360 View | J54: - Verwendet mit HYU-SC-01 (EAK0362L73A), VAG-SC-01 (EAK0370J05A), VAG-SC-01 (EAK0370J05A) - 360 Grad | K54: - Used with HYU-SC-01 (EAK0362L73A), VAG-SC-01 (EAK0370J05A), VAG-SC-01 (EAK0370J05A) - Vista 360 | L54: - Used with HYU-SC-01 (EAK0362L73A), VAG-SC-01 (EAK0370J05A), VAG-SC-01 (EAK0370J05A) - 360 View
G55: EAK0363J76A | H55: - Stand for Target EAK0362L62A | I55: Support pour cible EAK0362L62A | J55: Ständer für Target EAK0362L62A | K55: Soporte para diana EAK0362L62A | L55: - Stand for Target EAK0362L62A
...

Sheet ADAS 2026
B1: #VALUE! | D1: PRICE LIST 2026 | G1: ENGLISH | K1: Validity 2026.06.01 | L1: All the regions
B3: PRODUCT IMAGE | C3: PRODUCT TYPE | D3: FAMILY | E3: P/N | F3: MODEL | G3: DESCRIPTION | K3: List Price (Euro) | L3: Discount | M3: Net Price (ex works)
B4: #VALUE! | C4: EESEEU505B | D4: TRU-POINT | E4: EESEEU505B | F4: Tru-Point Calibration System | G4: =IF(VLOOKUP(E4,Language!G:L,HLOOKUP($G$1,Language!H$2:L$3,2,0),0)="","",VLOOKUP(E4,Language!G:L,HLOOKUP($G$1,Language!H$2:L$3,2,0),0)) -> Includes: - AC400 Clamps - Ride height targets - TIP target - 1 year Premium Free Subscription - CE Conform * Calibration targets and accessories sold separately | K4: 32595 | L4: 0.5 | M4: =+K4*(1-L4) -> 16297.5
B5: #VALUE! | C5: EESE900BKEU | D5: EZ-ADAS | E5: EESE900BKEU | F5: ADAS COMPONENT KIT - BASIC | G5: =IF(VLOOKUP(E5,Language!G:L,HLOOKUP($G$1,Language!H$2:L$3,2,0),0)="","",VLOOKUP(E5,Language!G:L,HLOOKUP($G$1,Language!H$2:L$3,2,0),0)) -> Includes: Target Stand, Alignment Fixture, Alignment Fixture w/ Laser, Laser Assembly (2), Alignment Plate, Tape Rule , Tape Rule Stand, Extension Arm (2). Forward Camera Targets (Honda, Acura, Hyundai, Kia, Mazda, Nissan, Infiniti, Audi, Volkswagen, Mercedes-Benz, Toyota, Lexus) | K5: 15675 | L5: 0.6004 | M5: =+K5*(1-L5) -> 6263.73
B6: #VALUE! | C6: EESE900DXEU | D6: EZ-ADAS | E6: EESE900DXEU | F6: ADAS COMPONENT KIT - DELUXE | G6: =IF(VLOOKUP(E6,Language!G:L,HLOOKUP($G$1,Language!H$2:L$3,2,0),0)="","",VLOOKUP(E6,Language!G:L,HLOOKUP($G$1,Language!H$2:L$3,2,0),0)) -> Includes: Target Stand, Alignment Fixture, Alignment Fixture w/ Laser, Laser Assembly (2), Alignment Plate, Tape Rule , Tape Rule Stand, Extension Arm (2), Rear Alignment Plate, Radar Alignment Stand, Front Radar Reflector (3). Forward Camera Targets (Honda, Acura, Hyundai, Kia, Mazda, Nissan, Infiniti, Audi, Volkswagen, Mercedes-Benz, Toyota, Lexus, Subaru, Mitsubishi). Rear Camera Targets (Audi, Volkswagen, Mercedes-Benz). Forward Radar Reflector (Honda, Acura, Mazda, Toyota, Lexus) | K6: 23515 | L6: 0.6314 | M6: =+K6*(1-L6) -> 8667.629

Sheet Accessories
B1: #VALUE! | D1: PRICE LIST 2026 | G1: ENGLISH | H1: Validity 2026.06.01 | I1: All the regions
B3: PRODUCT IMAGE | C3: CATEGORY | D3: P/N | E3: ITEM | F3: REQUIRES | G3: BRAND - CALIBRATION | H3: List Price (Euro) | I3: Discount | J3: Net Price (ex works)
B4: #VALUE! | C4: TRU-POINT & EZ-ADAS | D4: EAK0362L18A | E4: FIA-FC-01 | G4: =IF(VLOOKUP(D4,Language!G:L,HLOOKUP($G$1,Language!H$2:L$3,2,0),0)="","",VLOOKUP(D4,Language!G:L,HLOOKUP($G$1,Language!H$2:L$3,2,0),0)) -> - Alfa Romeo - Front Camera Target | H4: 1255 | I4: 0.4 | J4: =+H4*(1-I4) -> 753
B5: #VALUE! | C5: TRU-POINT & EZ-ADAS | D5: EAK0362L65A | E5: FOR-SC-01 | F5: - TGT-05 | G5: =IF(VLOOKUP(D5,Language!G:L,HLOOKUP($G$1,Language!H$2:L$3,2,0),0)="","",VLOOKUP(D5,Language!G:L,HLOOKUP($G$1,Language!H$2:L$3,2,0),0)) -> - Ford - 360 View | H5: 7319 | I5: 0.4 | J5: =+H5*(1-I5) -> 4391.4
B6: #VALUE! | C6: TRU-POINT & EZ-ADAS | D6: EAK0362L28A | E6: HON-FC-01 | G6: =IF(VLOOKUP(D6,Language!G:L,HLOOKUP($G$1,Language!H$2:L$3,2,0),0)="","",VLOOKUP(D6,Language!G:L,HLOOKUP($G$1,Language!H$2:L$3,2,0),0)) -> - Honda, Acura - Front Camera Target | H6: 314 | I6: 0.4 | J6: =+H6*(1-I6) -> 188.4
C7: TRU-POINT & EZ-ADAS | D7: EAK0362L11A | E7: HON-FC-02 | H7: 628 | I7: 0.4 | J7: =+H7*(1-I7) -> 376.8
C8: TRU-POINT & EZ-ADAS | D8: EAK0362L60A | E8: HON-SC-01 | H8: 1836 | I8: 0.4 | J8: =+H8*(1-I8) -> 1101.6
B9: #VALUE! | C9: TRU-POINT & EZ-ADAS | D9: EAK0362L13A | E9: HON-FC-03 | F9: - BKT-11 - BKT-12 | G9: =IF(VLOOKUP(D9,Language!G:L,HLOOKUP($G$1,Language!H$2:L$3,2,0),0)="","",VLOOKUP(D9,Language!G:L,HLOOKUP($G$1,Language!H$2:L$3,2,0),0)) -> - Honda - Front Camera Target | H9: 356 | I9: 0.4 | J9: =+H9*(1-I9) -> 213.6
B10: #VALUE! | C10: TRU-POINT & EZ-ADAS | D10: EAK0362L62A | E10: HON-SC-03 | F10: - Wing Target Cart (EAK0363J76A) | G10: =IF(VLOOKUP(D10,Language!G:L,HLOOKUP($G$1,Language!H$2:L$3,2,0),0)="","",VLOOKUP(D10,Language!G:L,HLOOKUP($G$1,Language!H$2:L$3,2,0),0)) -> - Honda - Blind Spot Camera | H10: 1255 | I10: 0.4 | J10: =+H10*(1-I10) -> 753
B11: #VALUE! | C11: TRU-POINT & EZ-ADAS | D11: EAK0362L29A | E11: HYU-FC-01 | G11: =IF(VLOOKUP(D11,Language!G:L,HLOOKUP($G$1,Language!H$2:L$3,2,0),0)="","",VLOOKUP(D11,Language!G:L,HLOOKUP($G$1,Language!H$2:L$3,2,0),0)) -> - Fiat Hyundai, Kia, Genesis Opel, Vauxhall Peugeot - Front Camera Target | H11: 210 | I11: 0.4 | J11: =+H11*(1-I11) -> 126
B12: #VALUE! | C12: TRU-POINT & EZ-ADAS | D12: EAK0362L73A | E12: HYU-SC-01 | G12: =IF(VLOOKUP(D12,Language!G:L,HLOOKUP($G$1,Language!H$2:L$3,2,0),0)="","",VLOOKUP(D12,Language!G:L,HLOOKUP($G$1,Language!H$2:L$3,2,0),0)) -> - Hyundai, Kia, Genesis - 360 View | H12: 3137 | I12: 0.4 | J12: =+H12*(1-I12) -> 1882.2
B13: #VALUE! | C13: TRU-POINT & EZ-ADAS | D13: EAK0362L27A | E13: MAZ-FC-01 | G13: =IF(VLOOKUP(D13,Language!G:L,HLOOKUP($G$1,Language!H$2:L$3,2,0),0)="","",VLOOKUP(D13,Language!G:L,HLOOKUP($G$1,Language!H$2:L$3,2,0),0)) -> - Mazda - Front Camera Target | H13: 252 | I13: 0.4 | J13: =+H13*(1-I13) -> 151.2
B14: #VALUE! | C14: TRU-POINT & EZ-ADAS | D14: EAK0362L33A | E14: MAZ-FC-02 | G14: =IF(VLOOKUP(D14,Language!G:L,HLOOKUP($G$1,Language!H$2:L$3,2,0),0)="","",VLOOKUP(D14,Language!G:L,HLOOKUP($G$1,Language!H$2:L$3,2,0),0)) -> - Mazda - Front Camera Target | H14: 252 | I14: 0.4 | J14: =+H14*(1-I14) -> 151.2
B15: #VALUE! | C15: TRU-POINT & EZ-ADAS | D15: EAK0362L25A | E15: MB-FC-01 | G15: =IF(VLOOKUP(D15,Language!G:L,HLOOKUP($G$1,Language!H$2:L$3,2,0),0)="","",VLOOKUP(D15,Language!G:L,HLOOKUP($G$1,Language!H$2:L$3,2,0),0)) -> - Mercedes-Benz, Volkswagen - Front Camera Target Requires NV-02 (EAK0362L47A) for Night Vision Short Range Calibration | H15: 314 | I15: 0.4 | J15: =+H15*(1-I15) -> 188.4
B16: #VALUE! | C16: TRU-POINT & EZ-ADAS | D16: EAK0362L32A | E16: MIT-FC-01 | G16: =IF(VLOOKUP(D16,Language!G:L,HLOOKUP($G$1,Language!H$2:L$3,2,0),0)="","",VLOOKUP(D16,Language!G:L,HLOOKUP($G$1,Language!H$2:L$3,2,0),0)) -> - Mitsubishi, Suzuki - Front Camera Target | H16: 189 | I16: 0.4 | J16: =+H16*(1-I16) -> 113.4
B17: #VALUE! | C17: TRU-POINT & EZ-ADAS | D17: EAK0362L64A | E17: MIT-SC-01 | G17: =IF(VLOOKUP(D17,Language!G:L,HLOOKUP($G$1,Language!H$2:L$3,2,0),0)="","",VLOOKUP(D17,Language!G:L,HLOOKUP($G$1,Language!H$2:L$3,2,0),0)) -> - 360 View | H17: 2510 | I17: 0.4 | J17: =+H17*(1-I17) -> 1506
B18: #VALUE! | C18: TRU-POINT & EZ-ADAS | D18: EAK0362L30A | E18: NIS-FC-01 | G18: =IF(VLOOKUP(D18,Language!G:L,HLOOKUP($G$1,Language!H$2:L$3,2,0),0)="","",VLOOKUP(D18,Language!G:L,HLOOKUP($G$1,Language!H$2:L$3,2,0),0)) | H18: 576 | I18: 0.4 | J18: =+H18*(1-I18) -> 345.6
B19: #VALUE! | C19: TRU-POINT & EZ-ADAS | D19: EAK0362L26A | E19: NIS-FC-02 | G19: =IF(VLOOKUP(D19,Language!G:L,HLOOKUP($G$1,Language!H$2:L$3,2,0),0)="","",VLOOKUP(D19,Language!G:L,HLOOKUP($G$1,Language!H$2:L$3,2,0),0)) -> - Mercedes-Benz, Nissan, Infiniti - Front Camera Target | H19: 262 | I19: 0.4 | J19: =+H19*(1-I19) -> 157.2
B20: #VALUE! | C20: TRU-POINT & EZ-ADAS | D20: EAK0362L20A | E20: NIS-FC-03 | G20: =IF(VLOOKUP(D20,Language!G:L,HLOOKUP($G$1,Language!H$2:L$3,2,0),0)="","",VLOOKUP(D20,Language!G:L,HLOOKUP($G$1,Language!H$2:L$3,2,0),0)) -> - Maserati, Nissan, Infiniti - Front Camera Target | H20: 523 | I20: 0.4 | J20: =+H20*(1-I20) -> 313.8
B21: #VALUE! | C21: TRU-POINT & EZ-ADAS | D21: EAK0388J67A | E21: NIS-SC-03 | F21: - TGT-06 | G21: =IF(VLOOKUP(D21,Language!G:L,HLOOKUP($G$1,Language!H$2:L$3,2,0),0)="","",VLOOKUP(D21,Language!G:L,HLOOKUP($G$1,Language!H$2:L$3,2,0),0)) -> - Nissan - Park Assist | H21: 1077 | I21: 0.4 | J21: =+H21*(1-I21) -> 646.2
C22: TRU-POINT & EZ-ADAS | D22: EAK0362L78A | E22: NIS-RC-01 | G22: =IF(VLOOKUP(D22,Language!G:L,HLOOKUP($G$1,Language!H$2:L$3,2,0),0)="","",VLOOKUP(D22,Language!G:L,HLOOKUP($G$1,Language!H$2:L$3,2,0),0)) -> - Rear Camera | H22: 1046 | I22: 0.4 | J22: =+H22*(1-I22) -> 627.6
B23: #VALUE! | C23: TRU-POINT & EZ-ADAS | D23: EAK0388J91A | E23: NIS-SC-01/02 | F23: - TGT-06 - includes: NIS-SC-02 - | G23: =IF(VLOOKUP(D23,Language!G:L,HLOOKUP($G$1,Language!H$2:L$3,2,0),0)="","",VLOOKUP(D23,Language!G:L,HLOOKUP($G$1,Language!H$2:L$3,2,0),0)) -> - Nissan - 360 View | H23: 2255 | I23: 0.4 | J23: =+H23*(1-I23) -> 1353
C24: TRU-POINT & EZ-ADAS | D24: EAK0362L44A | E24: NV-01 | H24: 1400 | I24: 0.4 | J24: =+H24*(1-I24) -> 840
B25: #VALUE! | C25: TRU-POINT & EZ-ADAS | D25: EAK0362L47A | E25: NV-02 | F25: - Thermal Tower | G25: =IF(VLOOKUP(D25,Language!G:L,HLOOKUP($G$1,Language!H$2:L$3,2,0),0)="","",VLOOKUP(D25,Language!G:L,HLOOKUP($G$1,Language!H$2:L$3,2,0),0)) -> - Mercedes-Benz - Night Vision Target | H25: 1046 | I25: 0.4 | J25: =+H25*(1-I25) -> 627.6
B26: #VALUE! | C26: TRU-POINT & EZ-ADAS | D26: EAK0362L45A | E26: RAD-04 | F26: - BKT-13 | G26: =IF(VLOOKUP(D26,Language!G:L,HLOOKUP($G$1,Language!H$2:L$3,2,0),0)="","",VLOOKUP(D26,Language!G:L,HLOOKUP($G$1,Language!H$2:L$3,2,0),0)) -> - Alfa Romeo, Fiat, Jeep, Seat, Skoda, Nissan, Infiniti, Renault, Audi, Bentley, Porsche, Volkswagen - Front Radar Target | H26: 1673 | I26: 0.4 | J26: =+H26*(1-I26) -> 1003.8
B27: #VALUE! | C27: TRU-POINT & EZ-ADAS | D27: EAK0370J11A | E27: RAD-05 | F27: - BKT-13 | G27: =IF(VLOOKUP(D27,Language!G:L,HLOOKUP($G$1,Language!H$2:L$3,2,0),0)="","",VLOOKUP(D27,Language!G:L,HLOOKUP($G$1,Language!H$2:L$3,2,0),0)) -> - Man, Seat, Skoda, Mercedes-Benz, Toyota, Audi, Lamborghini, Volkswagen - Front Radar Target | H27: 1360 | I27: 0.4 | J27: =+H27*(1-I27) -> 816
C28: TRU-POINT & EZ-ADAS | D28: EAA0531J03B | F28: - For Tru-Point Jan 2024 onwards | H28: 2555 | I28: 0.4 | J28: =+H28*(1-I28) -> 1533
B29: #VALUE! | C29: TRU-POINT & EZ-ADAS | D29: EAK0370J30A | E29: RAD-11 | F29: - Includes RAD-11 Base - Includes: base - Post- Cones: RAD01 (EAA0531J08A) RAD02 (EAA0531J09A) RAD03 (EAA0531J10A) RAD07 (EAA0531J11A) | G29: =IF(VLOOKUP(D29,Language!G:L,HLOOKUP($G$1,Language!H$2:L$3,2,0),0)="","",VLOOKUP(D29,Language!G:L,HLOOKUP($G$1,Language!H$2:L$3,2,0),0)) -> - Blind Spot Front Radar | H29: 3764 | I29: 0.4 | J29: =+H29*(1-I29) -> 2258.4
B30: #VALUE! | C30: TRU-POINT & EZ-ADAS | D30: EAK0362L19A | E30: REN-FC-01 | G30: =IF(VLOOKUP(D30,Language!G:L,HLOOKUP($G$1,Language!H$2:L$3,2,0),0)="","",VLOOKUP(D30,Language!G:L,HLOOKUP($G$1,Language!H$2:L$3,2,0),0)) -> - Renault, Opel, Vauxhall, Smart - Front Camera Target | H30: 941 | I30: 0.4 | J30: =+H30*(1-I30) -> 564.6
B31: #VALUE! | C31: TRU-POINT & EZ-ADAS | D31: EAK0362L37A | E31: SUB-FC-01 | G31: =IF(VLOOKUP(D31,Language!G:L,HLOOKUP($G$1,Language!H$2:L$3,2,0),0)="","",VLOOKUP(D31,Language!G:L,HLOOKUP($G$1,Language!H$2:L$3,2,0),0)) -> - Subaru - Front Camera Target | H31: 1255 | I31: 0.4 | J31: =+H31*(1-I31) -> 753
B32: #VALUE! | C32: TRU-POINT & EZ-ADAS | D32: EAK0362L38A | E32: SUB-FC-02 | G32: =IF(VLOOKUP(D32,Language!G:L,HLOOKUP($G$1,Language!H$2:L$3,2,0),0)="","",VLOOKUP(D32,Language!G:L,HLOOKUP($G$1,Language!H$2:L$3,2,0),0)) -> - Subaru - Front Camera Target | H32: 1255 | I32: 0.4 | J32: =+H32*(1-I32) -> 753
C33: TRU-POINT & EZ-ADAS | D33: EAK0388J65A | E33: SUB-FC-03 | H33: 654 | I33: 0.4 | J33: =+H33*(1-I33) -> 392.4
B34: #VALUE! | C34: TRU-POINT & EZ-ADAS | D34: EAK0362L74A | E34: SUZ-FC-01 | G34: =IF(VLOOKUP(D34,Language!G:L,HLOOKUP($G$1,Language!H$2:L$3,2,0),0)="","",VLOOKUP(D34,Language!G:L,HLOOKUP($G$1,Language!H$2:L$3,2,0),0)) -> - Suzuki - Front Camera Target | H34: 941 | I34: 0.4 | J34: =+H34*(1-I34) -> 564.6
B35: #VALUE! | C35: TRU-POINT & EZ-ADAS | D35: EAK0362L34A | E35: TOY-FC-01 | G35: =IF(VLOOKUP(D35,Language!G:L,HLOOKUP($G$1,Language!H$2:L$3,2,0),0)="","",VLOOKUP(D35,Language!G:L,HLOOKUP($G$1,Language!H$2:L$3,2,0),0)) -> - Toyota, Lexus - Front Camera Target | H35: 314 | I35: 0.4 | J35: =+H35*(1-I35) -> 188.4
B36: #VALUE! | C36: TRU-POINT & EZ-ADAS | D36: EAK0362L23A | E36: TOY-FC-02 | G36: =IF(VLOOKUP(D36,Language!G:L,HLOOKUP($G$1,Language!H$2:L$3,2,0),0)="","",VLOOKUP(D36,Language!G:L,HLOOKUP($G$1,Language!H$2:L$3,2,0),0)) -> - Toyota, Lexus - Front Camera Target | H36: 314 | I36: 0.4 | J36: =+H36*(1-I36) -> 188.4
B37: #VALUE! | C37: TRU-POINT & EZ-ADAS | D37: EAK0362L24A | E37: TOY-FC-03 | G37: =IF(VLOOKUP(D37,Language!G:L,HLOOKUP($G$1,Language!H$2:L$3,2,0),0)="","",VLOOKUP(D37,Language!G:L,HLOOKUP($G$1,Language!H$2:L$3,2,0),0)) -> - Toyota, Lexus - Front Camera Target | H37: 314 | I37: 0.4 | J37: =+H37*(1-I37) -> 188.4
B38: #VALUE! | C38: TRU-POINT & EZ-ADAS | D38: EAK0362L67A | E38: TOY-RC-01+TOY-RC-02 | G38: =IF(VLOOKUP(D38,Language!G:L,HLOOKUP($G$1,Language!H$2:L$3,2,0),0)="","",VLOOKUP(D38,Language!G:L,HLOOKUP($G$1,Language!H$2:L$3,2,0),0)) -> - Rear Camera Target and 360 View | H38: 941 | I38: 0.4 | J38: =+H38*(1-I38) -> 564.6
B39: #VALUE! | C39: TRU-POINT & EZ-ADAS | D39: EAK0362L31A | E39: VAG-FC-01 | G39: =IF(VLOOKUP(D39,Language!G:L,HLOOKUP($G$1,Language!H$2:L$3,2,0),0)="","",VLOOKUP(D39,Language!G:L,HLOOKUP($G$1,Language!H$2:L$3,2,0),0)) -> - MAN, Seat, Skoda, Audi, Bentley, Lamborghini, Porsche, Volkswagen - Front Camera Target | H39: 1255 | I39: 0.4 | J39: =+H39*(1-I39) -> 753
B40: #VALUE! | C40: TRU-POINT & EZ-ADAS | D40: EAK0370J10B | E40: VAG-FL-01 | F40: - BKT-13 | G40: =IF(VLOOKUP(D40,Language!G:L,HLOOKUP($G$1,Language!H$2:L$3,2,0),0)="","",VLOOKUP(D40,Language!G:L,HLOOKUP($G$1,Language!H$2:L$3,2,0),0)) -> - Lidar Calibration Target for Audi and Lamborghini - Front Lidar | H40: 3346 | I40: 0.4 | J40: =+H40*(1-I40) -> 2007.6
B41: #VALUE! | C41: TRU-POINT & EZ-ADAS | D41: EAK0370J05A | E41: VAG-SC-01 | F41: - TGT-05 | G41: =IF(VLOOKUP(D41,Language!G:L,HLOOKUP($G$1,Language!H$2:L$3,2,0),0)="","",VLOOKUP(D41,Language!G:L,HLOOKUP($G$1,Language!H$2:L$3,2,0),0)) -> - Skoda, Audi, Bentley, Lamborghini, Porsche, - Volkswagen 360 View | H41: 2301 | I41: 0.4 | J41: =+H41*(1-I41) -> 1380.6
...

Sheet Terms & Conditions
A1: GENERAL CONDITIONS FOR SALE AND SUPPLY
A3: 1. Definitions
A4: In these General Conditions for Sale and Supply the following expressions shall
A5: have the meaning as herein after set out.
A6: “The Conditions” means the present General Conditions for Sale and Supply.
A7: Snap-on Equipment means Snap-on Equipment s.r.l. a company with one
A8: shareholder only, with its registered office at Correggio (Reggio Emilia), Italy
A9: via Provinciale per Carpi n. 33.
A10: “The Customer” means any person, firm, corporation or legal assignee or
A11: successor of such person, firm or corporation.
A12: “The Goods” means those items which are specified in Snap-on Equipment
A13: written confirmation of order.
... A511: C805E 2015.11
