Workbook
Name AST: #REF!
Name AST: #REF!
Name AST: #REF!
Name Bez: #REF!
Name Cneu: #REF!
Name Cost: #REF!
Name Cost: #REF!
Name Cost: #REF!
Name EANneu: #REF!
Name Finntest: #REF!
Name Finntest: #REF!
Name Finntest: #REF!
Name ICTP: #REF!
Name ICTP: #REF!
Name ICTP: #REF!
Name LP: #REF!
Name LP: #REF!
Name LP: #REF!
Name LPneu: #REF!
Name Miteral: #REF!
Name Miteral: #REF!
Name Miteral: #REF!
Name n: #REF!
Name n: #REF!
Name n: #REF!
Name New: #REF!
Name NR: #REF!
Name NRA: #REF!
Name PN: #REF!
Name PN: #REF!
Name PN: #REF!
Name Semler: #REF!
Name Semler: #REF!
Name Semler: #REF!
Name Sigl: #REF!
Name Sigl: #REF!
Name Sigl: #REF!
Name Spakko: #REF!
Name Spakko: #REF!
Name Spakko: #REF!
Name UVP: #REF!
Name UVP: #REF!
Name UVP: #REF!
Name UVPA: #REF!
Name UVPneu: #REF!
Name Z.Sigl: #REF!
Name Z.Sigl: #REF!
Name Z.Sigl: #REF!

Sheet Language
B1: CEE & CIS | C1: ENGLISH | D1: CUSTOMER CODE | E1: CUSTOMER NAME | F1: COUNTRY | G1: PAYMENT TERM | H1: REFERENCED PRICE LIST | I1: CURRENCY | J1: CREDIT LIMIT
A2: ENGLISH | B2: MEA | C2: FRANÇAIS | D2: RÉF. CLIENT | E2: NOM CLIENT | F2: PAYS | G2: CONDITIONS DE PAIEMENT | H2: TARIFS RELATIFS | I2: MONNAIE | J2: PLAFOND DE CRÉDIT
A3: DEUTSCH | B3: Iberica | C3: DEUTSCH | D3: KUNDENREF. | E3: KUNDENNAME | F3: LAND | G3: ZAHLUNGSBEDINGUNGEN | H3: PREISBASIS | I3: WÄHRUNG | J3: KREDITRAHMEN
A4: FRANÇAIS | B4: Benelux | C4: ESPAÑOL | D4: CÓDIGO DE CLIENTE | E4: NOMBRE DEL CLIENTE | F4: PAÍS | G4: FORMA DE PAGO | H4: LISTADO PRECIOS | I4: MONEDA | J4: LÍMITE DE CRÉDITO
A5: ESPAÑOL | B5: North CH | C5: ITALIANO | D5: CODICE CLIENTE | E5: NOME DEL CLIENTE | F5: PAESE | G5: TERMINE DI PAGAMENTO | H5: LISTINO PREZZI DI RIFERIMENTO | I5: MONETA | J5: LIMITE DI CREDITO
A6: ITALIANO | B6: Poland
B7: Italy
A11: ENGLISH | B11: Effective date: | C11: V.1 This price list supersedes all previous price lists | D11: Sales Manager: | E11: Validity | F11: Base Price
A12: FRANÇAIS | B12: Date actuelle: | C12: V.1 Les tarifs du présent document remplacent les tarifs précédents | D12: Responsable de ventes: | E12: Validité | F12: Prix ​​de base
A13: DEUTSCH | B13: Gültigkeitdatum: | C13: V.1 Diese Preisliste ersetzt alle vorherigen Preislisten | D13: Vertriebsleiter: | E13: Gültigkeit | F13: Preise ab Werk
A14: ESPAÑOL | B14: Fecha efectiva: | C14: V.1 Esta lista de precios reemplaza todas las listas de precios anteriores | D14: Gerente de ventas: | E14: Validez | F14: Precio Base
A15: ITALIANO | B15: Data effettiva: | C15: V.1 Questo listino prezzi sostituisce tutti i listini precedenti | D15: Direttore delle vendite: | E15: Validità | F15: Prezzo base
A19: ENGLISH | B19: PRODUCT IMAGE | C19: P/N | D19: MODEL | E19: VOLTAGE | F19: DESCRIPTION | G19: PRODUCT TYPE | H19: SUB-CATEGORY | I19: SOFTWARE | J19: List Price | K19: Discount | L19: Net Price | M19: OEM | N19: CATEGORY | O19: ITEM | P19: COMPATIBILITY | Q19: Discount 2
A20: FRANÇAIS | B20: IMAGE DU PRODUIT | C20: P/N | D20: MODÈLE | E20: TENSION | F20: DESCRIPTION | G20: TYPE DE PRODUIT | H20: SOUS-CATÉGORIE | I20: SOFTWARE | J20: Liste des prix | K20: Rabais | L20: Prix ​​Net | M20: OEM | N20: CATÉGORIE | O20: ARTICLE | P20: COMPATIBILITÉ | Q20: Rabais 2
A21: DEUTSCH | B21: PRODUKTBILD | C21: P/N | D21: MODELL | E21: STROMSPANNUNG | F21: BESCHREIBUNG | G21: PRODUKTART | H21: UNTERKATEGORIE | I21: LOGICEL | J21: Preisliste | K21: Rabatt | L21: Nettopreis | M21: OEM | N21: KATEGORIE | O21: ARTIKEL | P21: KOMPATIBILITÄT | Q21: Rabatt 2
A22: ESPAÑOL | B22: IMAGEN DEL PRODUCTO | C22: P/N | D22: MODELO | E22: VOLTAJE | F22: DESCRIPCIÓN | G22: TIPO DE PRODUCTO | H22: SUBCATEGORÍA | I22: SOFTWARE | J22: Precio de lista | K22: Descuento | L22: Precio Neto | M22: OEM | N22: CATEGORÍA | O22: ARTÍCULO | P22: COMPATIBILIDAD | Q22: Descuento 2
A23: ITALIANO | B23: IMMAGINE DEL PRODOTTO | C23: P/N | D23: MODELLO | E23: VOLTAGGIO | F23: DESCRIZIONE | G23: TIPOLOGIA DI PRODOTTO | H23: SOTTOCATEGORIA | I23: SOFTWARE | J23: Prezzo di listino | K23: Sconto | L23: Prezzo Netto | M23: OEM | N23: CATEGORIA | O23: ARTICOLO | P23: COMPATIBILITÀ | Q23: Sconto 2
A26: ENGLISH | B26: WHEEL ALIGNERS
A27: FRANÇAIS | B27: CONTROLEURS DE GÉOMÉTRIE
A28: DEUTSCH | B28: ACHSMESSGERÄTE
A29: ESPAÑOL | B29: ALINEADORES DE RUEDAS
A30: ITALIANO | B30: ASSETTI RUOTE
A32: ENGLISH | B32: 3D CAMERA TECHNOLOGY WITH NEXT GENERATION SOFTWARE | C32: NEXT GENERATION
A33: FRANÇAIS | B33: TECHNOLOGIE CAMÉRA 3D AVEC LOGICIEL NOUVELLE GÉNÉRATION | C33: NOUVELLE GÉNÉRATION
A34: DEUTSCH | B34: 3D-KAMERATECHNIK MIT SOFTWARE DER NÄCHSTEN GENERATION | C34: NÄCHSTEN GENERATION
A35: ESPAÑOL | B35: TECNOLOGÍA DE CÁMARA 3D CON SOFTWARE DE NUEVA GENERACIÓN | C35: NUEVA GENERACIÓN
A36: ITALIANO | B36: TECNOLOGIA TELECAMERA 3D CON SOFTWARE DI NUOVA GENERAZIONE | C36: NUOVA GENERAZIONE
A38: ENGLISH | B38: NOTE: all above mentioned machines in RAL 5015b, 3000, 7040 keep the same net price as showed in this list. All other colors may be available with a LP surcharge of 280€
A39: FRANÇAIS | B39: Note: Toutes les machines ci-dessus en RAL 5015b, 3000, 7040 ont les prix identiques comme indiqués dans cette liste. Toutes les autres couleurs peuvent être disponibles à un supplément sur le prix tarif de 280€.
A40: DEUTSCH | B40: ACHTUNG: Alle oben aufgeführten Maschinen in RAL 5015b, 3000, 7040 haben identische Preise wie in dieser Liste aufgeführt. Alle anderen Farben haben einen Mehrpreis (LP) von of 280€
A41: ESPAÑOL | B41: NOTA: todas las máquinas mencionadas anteriormente en RAL 5015b, 3000, 7040 mantienen el mismo precio neto que se muestra en esta lista. Todos los demás colores pueden estar disponibles con un recargo LP de 280€
A42: ITALIANO | B42: NOTA: tutte le macchine sopra menzionate in RAL 5015b, 3000, 7040 mantengono lo stesso prezzo netto indicato in questa inserzione. Tutti gli altri colori potrebbero essere disponibili con un supplemento di € 280 LP
A45: ENGLISH | B45: Standard discount on ACCESSORIES Price List:
A46: FRANÇAIS | B46: Remise standard sur tarifs ACCESSOIRES:
A47: DEUTSCH | B47: Standardrabatt auf ZUBEHÖR laut Preisliste:
A48: ESPAÑOL | B48: Descuento estándar en la Lista de Precios de ACCESORIOS:
A49: ITALIANO | B49: Sconto Standard su Listino ACCESSORI:
A51: ENGLISH | B51: Standard discount on SPARE PARTS Price List:
A52: FRANÇAIS | B52: Remise standard sur tarifs PIÈCES DÉTACHÉES:
... A83: ITALIANO | B83: Approvato da:

Sheet DB Equipment
A1: P/N | B1: FAMILY | C1: CATEGORY - EN | D1: CATEGORY - DE | E1: CATEGORY - FR | F1: CATEGORY - ES | G1: CATEGORY - IT | H1: MODEL | I1: LANGUAGE | J1: VOLTAGE | K1: VCI | L1: DESCRIPTION - EN | M1: DESCRIPTION - DE | N1: DESCRIPTION - FR | O1: DESCRIPTION - ES | P1: DESCRIPTION - IT
A2: EESCDE137A | B2: PDL 4200 | C2: PDL | D2: PDL | E2: PDL | F2: PDL | G2: PDL | H2: PDL 4200 German | I2: German | L2: Including latest software release + free-of-charge updates (2 minimum) for one year, German version | M2: Including latest software release + free-of-charge updates (2 minimum) for one year, German version | N2: Including latest software release + free-of-charge updates (2 minimum) for one year, German version | O2: Including latest software release + free-of-charge updates (2 minimum) for one year, German version | P2: Including latest software release + free-of-charge updates (2 minimum) for one year, German version
A3: EESCFR137A | B3: PDL 4200 | C3: PDL | D3: PDL | E3: PDL | F3: PDL | G3: PDL | H3: PDL 4200 French | I3: French | L3: Including latest software release + free-of-charge updates (2 minimum) for one year, French version | M3: Including latest software release + free-of-charge updates (2 minimum) for one year, French version | N3: Including latest software release + free-of-charge updates (2 minimum) for one year, French version | O3: Including latest software release + free-of-charge updates (2 minimum) for one year, French version | P3: Including latest software release + free-of-charge updates (2 minimum) for one year, French version
A4: EESCIT137A | B4: PDL 4200 | C4: PDL | D4: PDL | E4: PDL | F4: PDL | G4: PDL | H4: PDL 4200 Italian | I4: Italian | L4: Including latest software release + free-of-charge updates (2 minimum) for one year, Italian version | M4: Including latest software release + free-of-charge updates (2 minimum) for one year, Italian version | N4: Including latest software release + free-of-charge updates (2 minimum) for one year, Italian version | O4: Including latest software release + free-of-charge updates (2 minimum) for one year, Italian version | P4: Including latest software release + free-of-charge updates (2 minimum) for one year, Italian version
A5: EESCPL137A | B5: PDL 4200 | C5: PDL | D5: PDL | E5: PDL | F5: PDL | G5: PDL | H5: PDL 4200 Polish | I5: Polish | L5: Including latest software release + free-of-charge updates (2 minimum) for one year, Polish version | M5: Including latest software release + free-of-charge updates (2 minimum) for one year, Polish version | N5: Including latest software release + free-of-charge updates (2 minimum) for one year, Polish version | O5: Including latest software release + free-of-charge updates (2 minimum) for one year, Polish version | P5: Including latest software release + free-of-charge updates (2 minimum) for one year, Polish version
A6: EESCPL137A x 5 | B6: PDL 4200 | C6: PDL | D6: PDL | E6: PDL | F6: PDL | G6: PDL | H6: PDL 4200 Polish | I6: Polish | L6: 5 unit order
A7: EESCPL137A x 10 | B7: PDL 4200 | C7: PDL | D7: PDL | E7: PDL | F7: PDL | G7: PDL | H7: PDL 4200 Polish | I7: Polish | L7: 10 unit order
A8: EESCEG137A | B8: PDL 4200 | C8: PDL | D8: PDL | E8: PDL | F8: PDL | G8: PDL | H8: PDL 4200 English | I8: English | L8: Including latest software release + free-of-charge updates (2 minimum) for one year, English version | M8: Including latest software release + free-of-charge updates (2 minimum) for one year, English version | N8: Including latest software release + free-of-charge updates (2 minimum) for one year, English version | O8: Including latest software release + free-of-charge updates (2 minimum) for one year, English version | P8: Including latest software release + free-of-charge updates (2 minimum) for one year, English version
A9: EESCDE135A | B9: PDL 7100 | C9: PDL | D9: PDL | E9: PDL | F9: PDL | G9: PDL | H9: PDL 7100 German | I9: German | L9: Including latest software release + free-of-charge updates (2 minimum) for one year, German version | M9: Including latest software release + free-of-charge updates (2 minimum) for one year, German version | N9: Including latest software release + free-of-charge updates (2 minimum) for one year, German version | O9: Including latest software release + free-of-charge updates (2 minimum) for one year, German version | P9: Including latest software release + free-of-charge updates (2 minimum) for one year, German version
A10: EESCFR135A | B10: PDL 7100 | C10: PDL | D10: PDL | E10: PDL | F10: PDL | G10: PDL | H10: PDL 7100 French | I10: French | L10: Including latest software release + free-of-charge updates (2 minimum) for one year, French version | M10: Including latest software release + free-of-charge updates (2 minimum) for one year, French version | N10: Including latest software release + free-of-charge updates (2 minimum) for one year, French version | O10: Including latest software release + free-of-charge updates (2 minimum) for one year, French version | P10: Including latest software release + free-of-charge updates (2 minimum) for one year, French version
A11: EESCIT135A | B11: PDL 7100 | C11: PDL | D11: PDL | E11: PDL | F11: PDL | G11: PDL | H11: PDL 7100 Italian | I11: Italian | L11: Including latest software release + free-of-charge updates (2 minimum) for one year, Italian version | M11: Including latest software release + free-of-charge updates (2 minimum) for one year, Italian version | N11: Including latest software release + free-of-charge updates (2 minimum) for one year, Italian version | O11: Including latest software release + free-of-charge updates (2 minimum) for one year, Italian version | P11: Including latest software release + free-of-charge updates (2 minimum) for one year, Italian version
A12: EESCPL135A | B12: PDL 7100 | C12: PDL | D12: PDL | E12: PDL | F12: PDL | G12: PDL | H12: PDL 7100 Polish | I12: Polish | L12: Including latest software release + free-of-charge updates (2 minimum) for one year, Polish version | M12: Including latest software release + free-of-charge updates (2 minimum) for one year, Polish version | N12: Including latest software release + free-of-charge updates (2 minimum) for one year, Polish version | O12: Including latest software release + free-of-charge updates (2 minimum) for one year, Polish version | P12: Including latest software release + free-of-charge updates (2 minimum) for one year, Polish version
A13: EESCPL135A x 5 | B13: PDL 7100 | C13: PDL | D13: PDL | E13: PDL | F13: PDL | G13: PDL | H13: PDL 7100 Polish | I13: Polish | L13: 5 unit order
A14: EESCPL135A x 10 | B14: PDL 7100 | C14: PDL | D14: PDL | E14: PDL | F14: PDL | G14: PDL | H14: PDL 7100 Polish | I14: Polish | L14: 10 unit order
A15: EESCEG135A | B15: PDL 7100 | C15: PDL | D15: PDL | E15: PDL | F15: PDL | G15: PDL | H15: PDL 7100 English | I15: English | L15: Including latest software release + free-of-charge updates (2 minimum) for one year, English version | M15: Including latest software release + free-of-charge updates (2 minimum) for one year, English version | N15: Including latest software release + free-of-charge updates (2 minimum) for one year, English version | O15: Including latest software release + free-of-charge updates (2 minimum) for one year, English version | P15: Including latest software release + free-of-charge updates (2 minimum) for one year, English version
A16: EEMSDE143A | B16: PDL 8000 | C16: PDL | D16: PDL | E16: PDL | F16: PDL | G16: PDL | H16: PDL 8000 German | I16: German | L16: Including latest software release + free-of-charge updates (2 minimum) for one year, German version Inkl. neueste Softwareversion + kostenlose Updates (mindestens 2) für 1 Jahr, deutsche Version | M16: Including latest software release + free-of-charge updates (2 minimum) for one year, German version Inkl. neueste Softwareversion + kostenlose Updates (mindestens 2) für 1 Jahr, deutsche Version | N16: Including latest software release + free-of-charge updates (2 minimum) for one year, German version Inkl. neueste Softwareversion + kostenlose Updates (mindestens 2) für 1 Jahr, deutsche Version | O16: Including latest software release + free-of-charge updates (2 minimum) for one year, German version Inkl. neueste Softwareversion + kostenlose Updates (mindestens 2) für 1 Jahr, deutsche Version | P16: Including latest software release + free-of-charge updates (2 minimum) for one year, German version Inkl. neueste Softwareversion + kostenlose Updates (mindestens 2) für 1 Jahr, deutsche Version
A17: EEMSPL143A | B17: PDL 8000 | C17: PDL | D17: PDL | E17: PDL | F17: PDL | G17: PDL | H17: PDL 8000 Polish | I17: Polish | L17: Including latest software release + free-of-charge updates (2 minimum) for one year, Polish version | M17: Including latest software release + free-of-charge updates (2 minimum) for one year, Polish version | N17: Including latest software release + free-of-charge updates (2 minimum) for one year, Polish version | O17: Including latest software release + free-of-charge updates (2 minimum) for one year, Polish version | P17: Including latest software release + free-of-charge updates (2 minimum) for one year, Polish version
A18: EEMSPL143A x 5 | B18: PDL 8000 | C18: PDL | D18: PDL | E18: PDL | F18: PDL | G18: PDL | H18: PDL 8000 Polish | I18: Polish | L18: 5 unit order
A19: EEMSPL143A x 10 | B19: PDL 8000 | C19: PDL | D19: PDL | E19: PDL | F19: PDL | G19: PDL | H19: PDL 8000 Polish | I19: Polish | L19: 10 unit order
A20: EEMSIT143A | B20: PDL 8000 | C20: PDL | D20: PDL | E20: PDL | F20: PDL | G20: PDL | H20: PDL 8000 Italian | I20: Italian | L20: Including latest software release + free-of-charge updates (2 minimum) for one year, Italian version | M20: Including latest software release + free-of-charge updates (2 minimum) for one year, Italian version | N20: Including latest software release + free-of-charge updates (2 minimum) for one year, Italian version | O20: Including latest software release + free-of-charge updates (2 minimum) for one year, Italian version | P20: Including latest software release + free-of-charge updates (2 minimum) for one year, Italian version
A21: EEMSFR143A | B21: PDL 8000 | C21: PDL | D21: PDL | E21: PDL | F21: PDL | G21: PDL | H21: PDL 8000 French | I21: French | L21: Including latest software release + free-of-charge updates (2 minimum) for one year, French version | M21: Including latest software release + free-of-charge updates (2 minimum) for one year, French version | N21: Including latest software release + free-of-charge updates (2 minimum) for one year, French version | O21: Including latest software release + free-of-charge updates (2 minimum) for one year, French version | P21: Including latest software release + free-of-charge updates (2 minimum) for one year, French version
A22: EEMSDE149A | B22: PDL 8200 | C22: PDL | D22: PDL | E22: PDL | F22: PDL | G22: PDL | H22: PDL 8200 German | I22: German | L22: Including latest software release + free-of-charge updates (2 minimum) for one year, German version | M22: Inkl. neueste Softwareversion + kostenlose Updates (mindestens 2) für 1 Jahr, deutsche Version | N22: Including latest software release + free-of-charge updates (2 minimum) for one year, German version | O22: Including latest software release + free-of-charge updates (2 minimum) for one year, German version | P22: Including latest software release + free-of-charge updates (2 minimum) for one year, German version
A23: EEMSPL149A | B23: PDL 8200 | C23: PDL | D23: PDL | E23: PDL | F23: PDL | G23: PDL | H23: PDL 8200 Polish | I23: Polish | L23: Including latest software release + free-of-charge updates (2 minimum) for one year, Polish version | M23: Including latest software release + free-of-charge updates (2 minimum) for one year, Polish version | N23: Including latest software release + free-of-charge updates (2 minimum) for one year, Polish version | O23: Including latest software release + free-of-charge updates (2 minimum) for one year, Polish version | P23: Including latest software release + free-of-charge updates (2 minimum) for one year, Polish version
A24: EEMSPL149A x 5 | B24: PDL 8200 | C24: PDL | D24: PDL | E24: PDL | F24: PDL | G24: PDL | H24: PDL 8200 Polish | I24: Polish | L24: 5 unit order
A25: EEMSPL149A x 10 | B25: PDL 8200 | C25: PDL | D25: PDL | E25: PDL | F25: PDL | G25: PDL | H25: PDL 8200 Polish | I25: Polish | L25: 10 unit order
A26: EEMSIT149A | B26: PDL 8200 | C26: PDL | D26: PDL | E26: PDL | F26: PDL | G26: PDL | H26: PDL 8200 Italian | I26: Italian | L26: Including latest software release + free-of-charge updates (2 minimum) for one year, Italian version | M26: Including latest software release + free-of-charge updates (2 minimum) for one year, Italian version | N26: Including latest software release + free-of-charge updates (2 minimum) for one year, Italian version | O26: Including latest software release + free-of-charge updates (2 minimum) for one year, Italian version | P26: Including latest software release + free-of-charge updates (2 minimum) for one year, Italian version
A27: EEMSFR149A | B27: PDL 8200 | C27: PDL | D27: PDL | E27: PDL | F27: PDL | G27: PDL | H27: PDL 8200 French | I27: French | L27: Including latest software release + free-of-charge updates (2 minimum) for one year, French version | M27: Including latest software release + free-of-charge updates (2 minimum) for one year, French version | N27: Including latest software release + free-of-charge updates (2 minimum) for one year, French version | O27: Including latest software release + free-of-charge updates (2 minimum) for one year, French version | P27: Including latest software release + free-of-charge updates (2 minimum) for one year, French version
A28: EEMSEG149A | B28: PDL 8200 | C28: PDL | D28: PDL | E28: PDL | F28: PDL | G28: PDL | H28: PDL 8200 English | I28: English | L28: Including latest software release + free-of-charge updates (2 minimum) for one year, English version | M28: Including latest software release + free-of-charge updates (2 minimum) for one year, English version | N28: Including latest software release + free-of-charge updates (2 minimum) for one year, English version | O28: Including latest software release + free-of-charge updates (2 minimum) for one year, English version | P28: Including latest software release + free-of-charge updates (2 minimum) for one year, English version
A29: EEPVEU118A | B29: TPMX tool | C29: TPMX | D29: TPMX | E29: TPMX | F29: TPMX | G29: TPMX | H29: TPMX tool | L29: Languages: English, Italian, Dutch, German, French, Polish, Spanish | M29: Languages: English, Italian, Dutch, German, French, Polish, Spanish | N29: Languages: English, Italian, Dutch, German, French, Polish, Spanish | O29: Languages: English, Italian, Dutch, German, French, Polish, Spanish | P29: Languages: English, Italian, Dutch, German, French, Polish, Spanish
A30: DECKY2N20020S000 | B30: Breeze IV | C30: A/C | D30: A/C | E30: A/C | F30: A/C | G30: A/C | H30: BREEZE IV with printer | J30: 220-240V 50/60 Hz | L30: Fully automatic A/C service station for recovery, recycling and recharging of different types of refrigerants. The innovative and exclusive solution allows to set the R134a or the HFO1234yf gas directly during activation in the workshop. 4,3” touch screen display. Thermal printer included. With its modular features, the machine can be configured to meet the most specific needs. The upgrade with the Gas Analyser detects the different components of the refrigerant, and the result provides information about their percentages. C.A.R. method (Compressor Assisted Recharge) With the advanced technology based on an innovative solenoid valve system, BREEZE IV consumes 20% less energy than the previous models. Futuristic design. Less than 30” to open the revolving control panel. BREEZE IV grants excellent maneuverability as a result of the considerable axial distance between the two wheels. User-friendly | M30: Vollautomatisches Klimaservicegerät für die Rückgewinnung, das Recycling und das Nachfüllen verschiedener Kältemittel. Die innovative und exklusive Lösung macht es möglich, das gewünschte Kältemittel erst bei der Aktivierung in der Werkstatt festzulegen. 4,3 Zoll-Touchscreen-Display. Inklusive Thermodrucker Dank des modularen Aufbaus kann das Gerät entsprechend den spezifischen Anforderungen konfiguriert werden. Durch ein Upgrade mit der optionalen Gasanalyse werden die verschiedenen Bestandteile des Kältemittels erkannt und als Prozentsatz angezeigt. C.A.R.-Methode (Compressor Assisted Recharge). Die fortschrittliche Technologie basiert auf einem innovativen Magnetventilsystem, wodurch BREEZE IV im Vergleich zu Vorgängermodellen über 20% weniger Energie verbraucht. Futuristisches Design. In weniger als 30 Sekunden Zugriff auf das drehende Bedienpanel. BREEZE IV garantiert ausgezeichnete Lenkbarkeit dank großem Achsabstand zwischen den beiden Rädern. Benutzerfreundlich | N30: Fully automatic A/C service station for recovery, recycling and recharging of different types of refrigerants. The innovative and exclusive solution allows to set the R134a or the HFO1234yf gas directly during activation in the workshop. 4,3” touch screen display. Thermal printer included. With its modular features, the machine can be configured to meet the most specific needs. The upgrade with the Gas Analyser detects the different components of the refrigerant, and the result provides information about their percentages. C.A.R. method (Compressor Assisted Recharge) With the advanced technology based on an innovative solenoid valve system, BREEZE IV consumes 20% less energy than the previous models. Futuristic design. Less than 30” to open the revolving control panel. BREEZE IV grants excellent maneuverability as a result of the considerable axial distance between the two wheels. User-friendly | O30: Fully automatic A/C service station for recovery, recycling and recharging of different types of refrigerants. The innovative and exclusive solution allows to set the R134a or the HFO1234yf gas directly during activation in the workshop. 4,3” touch screen display. Thermal printer included. With its modular features, the machine can be configured to meet the most specific needs. The upgrade with the Gas Analyser detects the different components of the refrigerant, and the result provides information about their percentages. C.A.R. method (Compressor Assisted Recharge) With the advanced technology based on an innovative solenoid valve system, BREEZE IV consumes 20% less energy than the previous models. Futuristic design. Less than 30” to open the revolving control panel. BREEZE IV grants excellent maneuverability as a result of the considerable axial distance between the two wheels. User-friendly | P30: Fully automatic A/C service station for recovery, recycling and recharging of different types of refrigerants. The innovative and exclusive solution allows to set the R134a or the HFO1234yf gas directly during activation in the workshop. 4,3” touch screen display. Thermal printer included. With its modular features, the machine can be configured to meet the most specific needs. The upgrade with the Gas Analyser detects the different components of the refrigerant, and the result provides information about their percentages. C.A.R. method (Compressor Assisted Recharge) With the advanced technology based on an innovative solenoid valve system, BREEZE IV consumes 20% less energy than the previous models. Futuristic design. Less than 30” to open the revolving control panel. BREEZE IV grants excellent maneuverability as a result of the considerable axial distance between the two wheels. User-friendly
A31: DECKY2NR00000000 | B31: Breeze IV | C31: A/C | D31: A/C | E31: A/C | F31: A/C | G31: A/C | H31: KIT R134A for BREEZE IV | L31: Refrigerant Kit NEXT R134a | M31: Kühlmitttel-Kit NEXT R134a | N31: Refrigerant Kit NEXT R134a | O31: Refrigerant Kit NEXT R134a | P31: Refrigerant Kit NEXT R134a
A32: DECKY2NH00000000 | B32: Breeze IV | C32: A/C | D32: A/C | E32: A/C | F32: A/C | G32: A/C | H32: KIT HFO for BREEZE IV | L32: Refrigerant Kit NEXT HFO1234yf | M32: Kühlmittel-Kit NEXT HFO1234yf | N32: Refrigerant Kit NEXT HFO1234yf | O32: Refrigerant Kit NEXT HFO1234yf | P32: Refrigerant Kit NEXT HFO1234yf
A33: DECKY2F20020S000 | B33: Blizzard Qtech IV | C33: A/C | D33: A/C | E33: A/C | F33: A/C | G33: A/C | H33: BLIZZARD QTECH IV | J33: 220-240V 50/60 Hz | L33: Fully automatic A/C service station for recovery, recycling and recharging of different types of refrigerants. Menu navigation is intuitive, professional, designed for an easy and rapid work with the machine. 7’’ color touchscreen. WI-FI connectivity. Hybrid and Nitrogen leak detection. The unit can handle the hermetic oil and dye cartridges, as well as the hermetic and refillable containers. The result is easy serviceability: less than 30” to open the revolving control panel and less than 2 minutes to remove both plastic covers and access all the internal components. QTECH IV grants excellent maneuverability as a result of the considerable axial distance between the two wheels. User-friendly features: pressure gauges and touch screen are perfectly inclined for excellent ergonomics. | M33: Vollautomatisches Klimaservicegerät für die Rückgewinnung, das Recycling und das Nachfüllen verschiedener Kältemittel Die Menüführung ist intuitiv, professionell, einfach und für ein schnelles und sicheres Arbeiten mit dem Gerät ausgelegt 7‘‘ Farb-Touchscreen. WIFI-Konnektivität Hybrid- und Stickstoff-Lecksuche Das Gerät ist sowohl mit luftdicht verschlossenen Kartuschen als auch mit luftdicht verschlossenen wiederbefüllbaren Behältern für Öl und Kontrastmittel ausgestattet Insgesamt einfachere Wartung: in weniger als 30 Sekunden Zugriff auf das drehende Bedienpanel und in weniger als 2 Minuten Entfernen der beiden Kunststoffabdeckungen und Zugriff auf alle innenliegenden Komponenten. QTECH IV garantiert ausgezeichnete Lenkbarkeit dank großem Achsabstand zwischen den beiden Rädern. Benutzerfreundliche Merkmale: Druckmesser und Touchscreen sind ergonomisch angeordnet. | N33: Fully automatic A/C service station for recovery, recycling and recharging of different types of refrigerants. Menu navigation is intuitive, professional, designed for an easy and rapid work with the machine. 7’’ color touchscreen. WI-FI connectivity. Hybrid and Nitrogen leak detection. The unit can handle the hermetic oil and dye cartridges, as well as the hermetic and refillable containers. The result is easy serviceability: less than 30” to open the revolving control panel and less than 2 minutes to remove both plastic covers and access all the internal components. QTECH IV grants excellent maneuverability as a result of the considerable axial distance between the two wheels. User-friendly features: pressure gauges and touch screen are perfectly inclined for excellent ergonomics. | O33: Fully automatic A/C service station for recovery, recycling and recharging of different types of refrigerants. Menu navigation is intuitive, professional, designed for an easy and rapid work with the machine. 7’’ color touchscreen. WI-FI connectivity. Hybrid and Nitrogen leak detection. The unit can handle the hermetic oil and dye cartridges, as well as the hermetic and refillable containers. The result is easy serviceability: less than 30” to open the revolving control panel and less than 2 minutes to remove both plastic covers and access all the internal components. QTECH IV grants excellent maneuverability as a result of the considerable axial distance between the two wheels. User-friendly features: pressure gauges and touch screen are perfectly inclined for excellent ergonomics. | P33: Fully automatic A/C service station for recovery, recycling and recharging of different types of refrigerants. Menu navigation is intuitive, professional, designed for an easy and rapid work with the machine. 7’’ color touchscreen. WI-FI connectivity. Hybrid and Nitrogen leak detection. The unit can handle the hermetic oil and dye cartridges, as well as the hermetic and refillable containers. The result is easy serviceability: less than 30” to open the revolving control panel and less than 2 minutes to remove both plastic covers and access all the internal components. QTECH IV grants excellent maneuverability as a result of the considerable axial distance between the two wheels. User-friendly features: pressure gauges and touch screen are perfectly inclined for excellent ergonomics.
A34: DECKY2FR00000000 | B34: Blizzard Qtech IV | C34: A/C | D34: A/C | E34: A/C | F34: A/C | G34: A/C | H34: KIT R134A for QTECH IV | L34: Refrigerant Kit FLAG R134a | M34: Kühlmitttel-Kit FLAG R134a | N34: Refrigerant Kit FLAG R134a | O34: Refrigerant Kit FLAG R134a | P34: Refrigerant Kit FLAG R134a
A35: DECKY2FH00000000 | B35: Blizzard Qtech IV | C35: A/C | D35: A/C | E35: A/C | F35: A/C | G35: A/C | H35: KIT HFO for QTECH IV | L35: Refrigerant Kit FLAG HFO1234yf | M35: Kühlmittel-Kit FLAG HFO1234yf | N35: Refrigerant Kit FLAG HFO1234yf | O35: Refrigerant Kit FLAG HFO1234yf | P35: Refrigerant Kit FLAG HFO1234yf
A36: DECKK6T5A090S00B | B36: Koolkare Dual Gas 12 | C36: A/C | D36: A/C | E36: A/C | F36: A/C | G36: A/C | H36: KOOLKARE DUAL GAS 12 | J36: 220-240V 50/60 Hz | L36: Fully automatic air conditioning recycling unit for R134a and HFO12234yf. Separate tanks, compressors, gauges, hoses, couplers, oil and dye bottles for the two gases. Easy-to-read 7" display. Fully automatic or manual recycling procedure. Hermetic oil and dye bottle systems. Advanced database, 2x12 kg tank, prepared for flushing function (software). + Nitrogen or forming gas leak check enabled software. + Oil function for hybrid vehicles + Refrigerant identifier ready | M36: Vollautomatisches Klimaanlagen-Wartungs- und Servicegerät für R134a und HFO1234yf. Separate Tanks, Kompressoren, Manometer, Schläuche, Anschlüsse, Öl- und Kontrastmittelkartuschen für die beiden Gase. Gut leserliches 7" Display. Vollautomatischer oder manueller Recyclingablauf. Luftdicht verschlossene Öl- und Kontrastmittelbehälter, Komfortdatenbank, 2 x 12 kg Kältemitteltank, vorbereitet für Spülfunktion (Software). + Softwarevorbereitung für die Lecksuche mittels Stickstoff oder Formiergas + Ölfunktion für Hybrid-Fahrzeuge + vorbereitet für Kältemittelidentifizierungsgerät | N36: Fully automatic air conditioning recycling unit for R134a and HFO12234yf. Separate tanks, compressors, gauges, hoses, couplers, oil and dye bottles for the two gases. Easy-to-read 7" display. Fully automatic or manual recycling procedure. Hermetic oil and dye bottle systems. Advanced database, 2x12 kg tank, prepared for flushing function (software). + Nitrogen or forming gas leak check enabled software. + Oil function for hybrid vehicles + Refrigerant identifier ready | O36: Fully automatic air conditioning recycling unit for R134a and HFO12234yf. Separate tanks, compressors, gauges, hoses, couplers, oil and dye bottles for the two gases. Easy-to-read 7" display. Fully automatic or manual recycling procedure. Hermetic oil and dye bottle systems. Advanced database, 2x12 kg tank, prepared for flushing function (software). + Nitrogen or forming gas leak check enabled software. + Oil function for hybrid vehicles + Refrigerant identifier ready | P36: Fully automatic air conditioning recycling unit for R134a and HFO12234yf. Separate tanks, compressors, gauges, hoses, couplers, oil and dye bottles for the two gases. Easy-to-read 7" display. Fully automatic or manual recycling procedure. Hermetic oil and dye bottle systems. Advanced database, 2x12 kg tank, prepared for flushing function (software). + Nitrogen or forming gas leak check enabled software. + Oil function for hybrid vehicles + Refrigerant identifier ready
A37: DECKXK456A170S51 | B37: KoolKare HD-S | C37: A/C | D37: A/C | E37: A/C | F37: A/C | G37: A/C | H37: KoolKare HD-S | J37: 220-240V 50/60 Hz | L37: Ideally suited for large AIRCO systems. Robust design with easy mobility around the workshop, easy-to-use controls and displays, fully automatic or manual recycling procedure, large 40 kg tank, gear pump for quick charging of bigger systems, database, automatic dye injection. | M37: Ideal geeignet für große AIRCO Anlagen. Robustes werkstatttaugliches Design, leicht verständliche Displayanzeigen und Bedienungselemente, vollautomatischer und manueller Recyclingablauf, großer 40 kg Tank, Zahnradpumpe zum schnellen Befüllen größerer Anlagen, Datenbank, Kontrastmitteleinspritzung | N37: Ideally suited for large AIRCO systems. Robust design with easy mobility around the workshop, easy-to-use controls and displays, fully automatic or manual recycling procedure, large 40 kg tank, gear pump for quick charging of bigger systems, database, automatic dye injection. | O37: Ideally suited for large AIRCO systems. Robust design with easy mobility around the workshop, easy-to-use controls and displays, fully automatic or manual recycling procedure, large 40 kg tank, gear pump for quick charging of bigger systems, database, automatic dye injection. | P37: Ideally suited for large AIRCO systems. Robust design with easy mobility around the workshop, easy-to-use controls and displays, fully automatic or manual recycling procedure, large 40 kg tank, gear pump for quick charging of bigger systems, database, automatic dye injection.
A38: DECKY1R74420S000 | B38: ECO2KARE | C38: A/C | D38: A/C | E38: A/C | F38: A/C | G38: A/C | H38: ECO2KARE | J38: 220-240V 50/60 Hz | L38: Fully automatic air conditioning service unit for emptying, servicing and filling R744 air conditioning systems | M38: Fully automatic air conditioning service unit for emptying, servicing and filling R744 air conditioning systems | N38: Fully automatic air conditioning service unit for emptying, servicing and filling R744 air conditioning systems | O38: Fully automatic air conditioning service unit for emptying, servicing and filling R744 air conditioning systems | P38: Fully automatic air conditioning service unit for emptying, servicing and filling R744 air conditioning systems
A39: DECKY1ATF020S000 | B39: ATF Gearkare | C39: ATF | D39: ATF | E39: ATF | F39: ATF | G39: ATF | H39: ATF Gearkare | J39: 220-240V 50/60 Hz | L39: ATF Gearkare | M39: ATF Gearkare | N39: ATF Gearkare | O39: ATF Gearkare | P39: ATF Gearkare
A40: DECKY1ATF0000SIM | B40: ATF Gearkare | C40: ATF | D40: ATF | E40: ATF | F40: ATF | G40: ATF | H40: ATF Gearkare Simulator | J40: 220-240V 50/60 Hz | L40: ATF Gearkare Simulator | M40: ATF Gearkare Simulator | N40: ATF Gearkare Simulator | O40: ATF Gearkare Simulator | P40: ATF Gearkare Simulator

Sheet DB Accessori
A1: P/N | B1: CATEGORY - EN | C1: CATEGORY - DE | D1: CATEGORY - FR | E1: CATEGORY - ES | F1: CATEGORY - IT | G1: MODEL - EN | H1: MODEL - DE | I1: MODEL - FR | J1: MODEL - ES | K1: MODEL - IT | L1: DESCRIPTION - EN | M1: DESCRIPTION - DE | N1: DESCRIPTION - FR | O1: DESCRIPTION - ES | P1: DESCRIPTION - IT | Q1: COMPATIBILITY - EN | R1: COMPATIBILITY - DE | S1: COMPATIBILITY - FR | T1: COMPATIBILITY - ES | U1: COMPATIBILITY - IT
A2: PDL
A3: EAX0068L01A | B3: PDL | C3: PDL | D3: PDL | E3: PDL | F3: PDL | G3: Adaptor cable DA-5 | H3: Adapterkabel DA-5 zum Anschluss der alten Adapterkabel | I3: Adaptor cable DA-7 | J3: Adaptor cable DA-8 | K3: Adaptor cable DA-9 | L3: Adaptor cable DA-10 | M3: Adapterkabel DA-5 zum Anschluss der alten Adapterkabel | N3: Adaptor cable DA-12 | O3: Adaptor cable DA-13 | P3: Adaptor cable DA-14 | Q3: PDL 3000, 3200, 4000, 4100, 5000, 5500, 5600, 7100, 8000, 8100 | R3: PDL 3000, 3200, 4000, 4100, 5000, 5500, 5600, 7100, 8000, 8100 | S3: PDL 3000, 3200, 4000, 4100, 5000, 5500, 5600, 7100, 8000, 8100 | T3: PDL 3000, 3200, 4000, 4100, 5000, 5500, 5600, 7100, 8000, 8100 | U3: PDL 3000, 3200, 4000, 4100, 5000, 5500, 5600, 7100, 8000, 8100
A4: EAX0068L00C | B4: PDL | C4: PDL | D4: PDL | E4: PDL | F4: PDL | G4: OBDII data cable w/o light (16-pin cable) | H4: OBDII Datenkabel ohne Licht (16-adriges Kabel) | I4: OBDII data cable w/o light (16-pin cable) | J4: OBDII data cable w/o light (16-pin cable) | K4: OBDII data cable w/o light (16-pin cable) | L4: OBDII data cable w/o light (16-pin cable) | M4: OBDII Datenkabel ohne Licht (16-adriges Kabel) | N4: OBDII data cable w/o light (16-pin cable) | O4: OBDII data cable w/o light (16-pin cable) | P4: OBDII data cable w/o light (16-pin cable) | Q4: PDL 3000, 3200, 4000, 4100, 5000, 5500, 7100 | R4: PDL 3000, 3200, 4000, 4100, 5000, 5500, 7100 | S4: PDL 3000, 3200, 4000, 4100, 5000, 5500, 7100 | T4: PDL 3000, 3200, 4000, 4100, 5000, 5500, 7100 | U4: PDL 3000, 3200, 4000, 4100, 5000, 5500, 7100
A5: EAX0068L26A | B5: PDL | C5: PDL | D5: PDL | E5: PDL | F5: PDL | G5: OBDII data cable w/ light (16-pin cable) | H5: OBDII Datenkabel mit Licht (16-adriges Kabel) | I5: OBDII data cable w/ light (16-pin cable) | J5: OBDII data cable w/ light (16-pin cable) | K5: OBDII data cable w/ light (16-pin cable) | L5: OBDII data cable w/ light (16-pin cable) | M5: OBDII Datenkabel mit Licht (16-adriges Kabel) | N5: OBDII data cable w/ light (16-pin cable) | O5: OBDII data cable w/ light (16-pin cable) | P5: OBDII data cable w/ light (16-pin cable) | Q5: PDL 4000, 4100, 5000, 5500, 5600, 7100, 8000, 8100 | R5: PDL 4000, 4100, 5000, 5500, 5600, 7100, 8000, 8100 | S5: PDL 4000, 4100, 5000, 5500, 5600, 7100, 8000, 8100 | T5: PDL 4000, 4100, 5000, 5500, 5600, 7100, 8000, 8100 | U5: PDL 4000, 4100, 5000, 5500, 5600, 7100, 8000, 8100
A6: EAX0072L17A | B6: PDL | C6: PDL | D6: PDL | E6: PDL | F6: PDL | G6: DA-4EA Ethernet DOIP data cable | H6: DA-4EA Ethernet DOIP Datenkabel | I6: DA-4EA Ethernet DOIP data cable | J6: DA-4EA Ethernet DOIP data cable | K6: DA-4EA Ethernet DOIP data cable | L6: DA-4EA Ethernet DOIP data cable | M6: DA-4EA Ethernet DOIP Datenkabel | N6: DA-4EA Ethernet DOIP data cable | O6: DA-4EA Ethernet DOIP data cable | P6: DA-4EA Ethernet DOIP data cable | Q6: PDL 3200, 4100, 5500, 5600, 7100, 8000, 8100 | R6: PDL 3200, 4100, 5500, 5600, 7100, 8000, 8100 | S6: PDL 3200, 4100, 5500, 5600, 7100, 8000, 8100 | T6: PDL 3200, 4100, 5500, 5600, 7100, 8000, 8100 | U6: PDL 3200, 4100, 5500, 5600, 7100, 8000, 8100
A7: 2-03965A | B7: PDL | C7: PDL | D7: PDL | E7: PDL | F7: PDL | G7: Soft Case | H7: Transportkoffer (Soft Case) | I7: Soft Case | J7: Soft Case | K7: Soft Case | L7: Soft Case | M7: Transportkoffer (Soft Case) | N7: Soft Case | O7: Soft Case | P7: Soft Case | Q7: PDL 3200, 4100, 5600, 7100, 8000, 8100 | R7: PDL 3200, 4100, 5600, 7100, 8000, 8100 | S7: PDL 3200, 4100, 5600, 7100, 8000, 8100 | T7: PDL 3200, 4100, 5600, 7100, 8000, 8100 | U7: PDL 3200, 4100, 5600, 7100, 8000, 8100
A8: EAC0111L76A3 | B8: PDL | C8: PDL | D8: PDL | E8: PDL | F8: PDL | G8: Screen Protector 3 Pack | H8: Bildschirmschutz (3 Satz) | I8: Screen Protector 3 Pack | J8: Screen Protector 3 Pack | K8: Screen Protector 3 Pack | L8: Screen Protector 3 Pack | M8: Bildschirmschutz (3 Satz) | N8: Screen Protector 3 Pack | O8: Screen Protector 3 Pack | P8: Screen Protector 3 Pack | Q8: PDL 4000, 4100, 5600, 8000, 8100 | R8: PDL 4000, 4100, 5600, 8000, 8100 | S8: PDL 4000, 4100, 5600, 8000, 8100 | T8: PDL 4000, 4100, 5600, 8000, 8100 | U8: PDL 4000, 4100, 5600, 8000, 8100
A9: EESP115A-3.2 | B9: PDL | C9: PDL | D9: PDL | E9: PDL | F9: PDL | G9: PDL 3200 Software update for 1 year (2 minimum per year) | H9: PDL 3200 Software-Update für 1 Jahr (mindestens 2 pro Jahr) | I9: PDL 3200 Software update for 1 year (2 minimum per year) | J9: PDL 3200 Software update for 1 year (2 minimum per year) | K9: PDL 3200 Software update for 1 year (2 minimum per year) | L9: PDL 3200 Software update for 1 year (2 minimum per year) | M9: PDL 3200 Software-Update für 1 Jahr (mindestens 2 pro Jahr) | N9: PDL 3200 Software update for 1 year (2 minimum per year) | O9: PDL 3200 Software update for 1 year (2 minimum per year) | P9: PDL 3200 Software update for 1 year (2 minimum per year) | Q9: PDL 3200 | R9: PDL 3200 | S9: PDL 3200 | T9: PDL 3200 | U9: PDL 3200
A10: EESP116A-3.2 | B10: PDL | C10: PDL | D10: PDL | E10: PDL | F10: PDL | G10: PDL 3200 Software update for 1 year (2 minimum per year) after termination plus charge for re-activation | H10: PDL 3200 Software-Update für 1 Jahr (mindestens 2 pro Jahr) nach Kündigung, plus Gebühr für Reaktivierung | I10: PDL 3200 Software update for 1 year (2 minimum per year) after termination plus charge for re-activation | J10: PDL 3200 Software update for 1 year (2 minimum per year) after termination plus charge for re-activation | K10: PDL 3200 Software update for 1 year (2 minimum per year) after termination plus charge for re-activation | L10: PDL 3200 Software update for 1 year (2 minimum per year) after termination plus charge for re-activation | M10: PDL 3200 Software-Update für 1 Jahr (mindestens 2 pro Jahr) nach Kündigung, plus Gebühr für Reaktivierung | N10: PDL 3200 Software update for 1 year (2 minimum per year) after termination plus charge for re-activation | O10: PDL 3200 Software update for 1 year (2 minimum per year) after termination plus charge for re-activation | P10: PDL 3200 Software update for 1 year (2 minimum per year) after termination plus charge for re-activation | Q10: PDL 3200 | R10: PDL 3200 | S10: PDL 3200 | T10: PDL 3200 | U10: PDL 3200
A11: EESP118A-3.2 | B11: PDL | C11: PDL | D11: PDL | E11: PDL | F11: PDL | G11: PDL 3200 Software update for 2 years (2 minimum per year) | H11: PDL 3200 Software-Update für 2 Jahre (mindestens 2 pro Jahr) | I11: PDL 3200 Software update for 2 years (2 minimum per year) | J11: PDL 3200 Software update for 2 years (2 minimum per year) | K11: PDL 3200 Software update for 2 years (2 minimum per year) | L11: PDL 3200 Software update for 2 years (2 minimum per year) | M11: PDL 3200 Software-Update für 2 Jahre (mindestens 2 pro Jahr) | N11: PDL 3200 Software update for 2 years (2 minimum per year) | O11: PDL 3200 Software update for 2 years (2 minimum per year) | P11: PDL 3200 Software update for 2 years (2 minimum per year) | Q11: PDL 3200 | R11: PDL 3200 | S11: PDL 3200 | T11: PDL 3200 | U11: PDL 3200
A12: EESP115A-4.1 | B12: PDL | C12: PDL | D12: PDL | E12: PDL | F12: PDL | G12: PDL 4100 Software update for 1 year (2 minimum per year) | H12: PDL 4100 Software-Update für 1 Jahr (mindestens 2 pro Jahr) | I12: PDL 4100 Software update for 1 year (2 minimum per year) | J12: PDL 4100 Software update for 1 year (2 minimum per year) | K12: PDL 4100 Software update for 1 year (2 minimum per year) | L12: PDL 4100 Software update for 1 year (2 minimum per year) | M12: PDL 4100 Software-Update für 1 Jahr (mindestens 2 pro Jahr) | N12: PDL 4100 Software update for 1 year (2 minimum per year) | O12: PDL 4100 Software update for 1 year (2 minimum per year) | P12: PDL 4100 Software update for 1 year (2 minimum per year) | Q12: PDL 4100 | R12: PDL 4100 | S12: PDL 4100 | T12: PDL 4100 | U12: PDL 4100
A13: EESP116A-4.1 | B13: PDL | C13: PDL | D13: PDL | E13: PDL | F13: PDL | G13: PDL 4100 Software update for 1 year (2 minimum per year) after termination plus charge for re-activation | H13: PDL 4100Software-Update für 1 Jahr (mindestens 2 pro Jahr) nach Kündigung, plus Gebühr für Reaktivierung | I13: PDL 4100 Software update for 1 year (2 minimum per year) after termination plus charge for re-activation | J13: PDL 4100 Software update for 1 year (2 minimum per year) after termination plus charge for re-activation | K13: PDL 4100 Software update for 1 year (2 minimum per year) after termination plus charge for re-activation | L13: PDL 4100 Software update for 1 year (2 minimum per year) after termination plus charge for re-activation | M13: PDL 4100Software-Update für 1 Jahr (mindestens 2 pro Jahr) nach Kündigung, plus Gebühr für Reaktivierung | N13: PDL 4100 Software update for 1 year (2 minimum per year) after termination plus charge for re-activation | O13: PDL 4100 Software update for 1 year (2 minimum per year) after termination plus charge for re-activation | P13: PDL 4100 Software update for 1 year (2 minimum per year) after termination plus charge for re-activation | Q13: PDL 4100 | R13: PDL 4100 | S13: PDL 4100 | T13: PDL 4100 | U13: PDL 4100
A14: EESP118A-4.1 | B14: PDL | C14: PDL | D14: PDL | E14: PDL | F14: PDL | G14: PDL 4100 Software update for 2 years (2 minimum per year) | H14: PDL 4100 Software-Update für 2 Jahre (mindestens 2 pro Jahr) | I14: PDL 4100 Software update for 2 years (2 minimum per year) | J14: PDL 4100 Software update for 2 years (2 minimum per year) | K14: PDL 4100 Software update for 2 years (2 minimum per year) | L14: PDL 4100 Software update for 2 years (2 minimum per year) | M14: PDL 4100 Software-Update für 2 Jahre (mindestens 2 pro Jahr) | N14: PDL 4100 Software update for 2 years (2 minimum per year) | O14: PDL 4100 Software update for 2 years (2 minimum per year) | P14: PDL 4100 Software update for 2 years (2 minimum per year) | Q14: PDL 4100 | R14: PDL 4100 | S14: PDL 4100 | T14: PDL 4100 | U14: PDL 4100
... A42: EAK0294B22A | B42: PDL | C42: PDL | D42: PDL | E42: PDL | F42: PDL | G42: Set of 4 probes for lab scope | H42: Prüfspitzensatz für Laborskop, 4 Stück | I42: Set of 4 probes for lab scope | J42: Set of 4 probes for lab scope | K42: Set of 4 probes for lab scope | L42: Set of 4 probes for lab scope | M42: Prüfspitzensatz für Laborskop, 4 Stück | N42: Set of 4 probes for lab scope | O42: Set of 4 probes for lab scope | P42: Set of 4 probes for lab scope | Q42: PDL 5500, PDL 5600, PDL 8000 | R42: PDL 5500, PDL 5600, PDL 8000 | S42: PDL 5500, PDL 5600, PDL 8000 | T42: PDL 5500, PDL 5600, PDL 8000 | U42: PDL 5500, PDL 5600, PDL 8000
B43: AC
A44: DECKKIT.HYBRID | B44: A/C | C44: A/C | D44: A/C | E44: A/C | F44: A/C | G44: Kit Hybrid Upgrade option HFO1234yf and R134a | H44: Hybrid-Upgradekit für HFO1234yf und R134a | I44: Kit Hybrid Upgrade option HFO1234yf and R134a | J44: Kit Hybrid Upgrade option HFO1234yf and R134a | K44: Kit Hybrid Upgrade option HFO1234yf and R134a | L44: Kit Hybrid Upgrade option HFO1234yf and R134a | M44: Hybrid-Upgradekit für HFO1234yf und R134a | N44: Kit Hybrid Upgrade option HFO1234yf and R134a | O44: Kit Hybrid Upgrade option HFO1234yf and R134a | P44: Kit Hybrid Upgrade option HFO1234yf and R134a | Q44: Breeze IV | R44: Breeze IV | S44: Breeze IV | T44: Breeze IV | U44: Breeze IV
A45: DECKXS180.000000 | B45: A/C | C45: A/C | D45: A/C | E45: A/C | F45: A/C | G45: Gas identifier HFO for single and dual gas units | H45: Kältemittelidentifizierungsgerät HFO für Ein- und Dualgas-Geräte | I45: Gas identifier HFO for single and dual gas units | J45: Gas identifier HFO for single and dual gas units | K45: Gas identifier HFO for single and dual gas units | L45: Gas identifier HFO for single and dual gas units | M45: Kältemittelidentifizierungsgerät HFO für Ein- und Dualgas-Geräte | N45: Gas identifier HFO for single and dual gas units | O45: Gas identifier HFO for single and dual gas units | P45: Gas identifier HFO for single and dual gas units | Q45: Dual Gas, Qtech III | R45: Dual Gas, Qtech III | S45: Dual Gas, Qtech III | T45: Dual Gas, Qtech III | U45: Dual Gas, Qtech III
A46: DECKKIT.GAS.R134 | B46: A/C | C46: A/C | D46: A/C | E46: A/C | F46: A/C | G46: Adapter kit R134a for gas analiser KIT.GAS | H46: Adapterkit R134a für Gastester | I46: Adapter kit R134a for gas analiser KIT.GAS | J46: Adapter kit R134a for gas analiser KIT.GAS | K46: Adapter kit R134a for gas analiser KIT.GAS | L46: Adapter kit R134a for gas analiser KIT.GAS | M46: Adapterkit R134a für Gastester | N46: Adapter kit R134a for gas analiser KIT.GAS | O46: Adapter kit R134a for gas analiser KIT.GAS | P46: Adapter kit R134a for gas analiser KIT.GAS | Q46: Breeze IV, Qtech IV | R46: Breeze IV, Qtech IV | S46: Breeze IV, Qtech IV | T46: Breeze IV, Qtech IV | U46: Breeze IV, Qtech IV
A47: DECKKIT.WIFI-N | B47: A/C | C47: A/C | D47: A/C | E47: A/C | F47: A/C | G47: Connectivity kit EVO | H47: Vernetzungskit EVO | I47: Connectivity kit EVO | J47: Connectivity kit EVO | K47: Connectivity kit EVO | L47: Connectivity kit EVO | M47: Vernetzungskit EVO | N47: Connectivity kit EVO | O47: Connectivity kit EVO | P47: Connectivity kit EVO | Q47: Breeze IV | R47: Breeze IV | S47: Breeze IV | T47: Breeze IV | U47: Breeze IV
A48: DECKTUB1148 | B48: A/C | C48: A/C | D48: A/C | E48: A/C | F48: A/C | G48: R134A Service hose 6 m, red, for QTECH II / III units and Breeze, male/female | H48: Serviceschlauch 6 m | I48: R134A Service hose 6 m, red, for QTECH II / III units and Breeze, male/female | J48: R134A Service hose 6 m, red, for QTECH II / III units and Breeze, male/female | K48: R134A Service hose 6 m, red, for QTECH II / III units and Breeze, male/female | L48: R134A Service hose 6 m, red, for QTECH II / III units and Breeze, male/female | M48: Serviceschlauch 6 m | N48: R134A Service hose 6 m, red, for QTECH II / III units and Breeze, male/female | O48: R134A Service hose 6 m, red, for QTECH II / III units and Breeze, male/female | P48: R134A Service hose 6 m, red, for QTECH II / III units and Breeze, male/female | Q48: All A/C machines | R48: All A/C machines | S48: All A/C machines | T48: All A/C machines | U48: All A/C machines
A49: DECKTUB1149 | B49: A/C | C49: A/C | D49: A/C | E49: A/C | F49: A/C | G49: R134A Service hose 6 m, blue, for QTECH II / III units and Breeze, male/female | H49: Serviceschlauch 6 m | I49: R134A Service hose 6 m, blue, for QTECH II / III units and Breeze, male/female | J49: R134A Service hose 6 m, blue, for QTECH II / III units and Breeze, male/female | K49: R134A Service hose 6 m, blue, for QTECH II / III units and Breeze, male/female | L49: R134A Service hose 6 m, blue, for QTECH II / III units and Breeze, male/female | M49: Serviceschlauch 6 m | N49: R134A Service hose 6 m, blue, for QTECH II / III units and Breeze, male/female | O49: R134A Service hose 6 m, blue, for QTECH II / III units and Breeze, male/female | P49: R134A Service hose 6 m, blue, for QTECH II / III units and Breeze, male/female | Q49: All A/C machines | R49: All A/C machines | S49: All A/C machines | T49: All A/C machines | U49: All A/C machines
A50: DECKGRTUB0001 | B50: A/C | C50: A/C | D50: A/C | E50: A/C | F50: A/C | G50: KoolKare nitogen/forming gas hose kit; for connection to a nitrogen or forming gas fitting, equipment end with hose and quick coupling. Spare parts, accessories as standard option with a Koolkare nitrogen/forming gas option | H50: KoolKare Schlauchsatz ; zum Anschluss an eine Stickstoff- bzw. Formiergasarmatur, inkl. Schlauch und Schnellkupplung geräteseitig. Ersatzteil, da Standardzubehör eines KK mit Stickstoff-/Formiergasoption. | I50: KoolKare nitogen/forming gas hose kit; for connection to a nitrogen or forming gas fitting, equipment end with hose and quick coupling. Spare parts, accessories as standard option with a Koolkare nitrogen/forming gas option | J50: KoolKare nitogen/forming gas hose kit; for connection to a nitrogen or forming gas fitting, equipment end with hose and quick coupling. Spare parts, accessories as standard option with a Koolkare nitrogen/forming gas option | K50: KoolKare nitogen/forming gas hose kit; for connection to a nitrogen or forming gas fitting, equipment end with hose and quick coupling. Spare parts, accessories as standard option with a Koolkare nitrogen/forming gas option | L50: KoolKare nitogen/forming gas hose kit; for connection to a nitrogen or forming gas fitting, equipment end with hose and quick coupling. Spare parts, accessories as standard option with a Koolkare nitrogen/forming gas option | M50: KoolKare Schlauchsatz ; zum Anschluss an eine Stickstoff- bzw. Formiergasarmatur, inkl. Schlauch und Schnellkupplung geräteseitig. Ersatzteil, da Standardzubehör eines KK mit Stickstoff-/Formiergasoption. | N50: KoolKare nitogen/forming gas hose kit; for connection to a nitrogen or forming gas fitting, equipment end with hose and quick coupling. Spare parts, accessories as standard option with a Koolkare nitrogen/forming gas option | O50: KoolKare nitogen/forming gas hose kit; for connection to a nitrogen or forming gas fitting, equipment end with hose and quick coupling. Spare parts, accessories as standard option with a Koolkare nitrogen/forming gas option | P50: KoolKare nitogen/forming gas hose kit; for connection to a nitrogen or forming gas fitting, equipment end with hose and quick coupling. Spare parts, accessories as standard option with a Koolkare nitrogen/forming gas option | Q50: Qtech IV, Dual Gas, Qtech III | R50: Qtech IV, Dual Gas, Qtech III | S50: Qtech IV, Dual Gas, Qtech III | T50: Qtech IV, Dual Gas, Qtech III | U50: Qtech IV, Dual Gas, Qtech III
A51: DECKAEK322 | B51: A/C | C51: A/C | D51: A/C | E51: A/C | F51: A/C | G51: Bottle of Saniflux liquid (1000 ml) | H51: Flasche Saniflux Liquid (1000 ml) | I51: Bottle of Saniflux liquid (1000 ml) | J51: Bottle of Saniflux liquid (1000 ml) | K51: Bottle of Saniflux liquid (1000 ml) | L51: Bottle of Saniflux liquid (1000 ml) | M51: Flasche Saniflux Liquid (1000 ml) | N51: Bottle of Saniflux liquid (1000 ml) | O51: Bottle of Saniflux liquid (1000 ml) | P51: Bottle of Saniflux liquid (1000 ml) | Q51: All A/C machines | R51: All A/C machines | S51: All A/C machines | T51: All A/C machines | U51: All A/C machines
A52: DECKAEK275 | B52: A/C | C52: A/C | D52: A/C | E52: A/C | F52: A/C | G52: Oil bottle PAG100, R134, HFO1234yf, mechanical and electrical compressor, 6 x 250 ml | H52: Ölbehälter PAG100, R134, HFO1234yf, 6 x 250 ml | I52: Oil bottle PAG100, R134, HFO1234yf, mechanical and electrical compressor, 6 x 250 ml | J52: Oil bottle PAG100, R134, HFO1234yf, mechanical and electrical compressor, 6 x 250 ml | K52: Oil bottle PAG100, R134, HFO1234yf, mechanical and electrical compressor, 6 x 250 ml | L52: Oil bottle PAG100, R134, HFO1234yf, mechanical and electrical compressor, 6 x 250 ml | M52: Ölbehälter PAG100, R134, HFO1234yf, 6 x 250 ml | N52: Oil bottle PAG100, R134, HFO1234yf, mechanical and electrical compressor, 6 x 250 ml | O52: Oil bottle PAG100, R134, HFO1234yf, mechanical and electrical compressor, 6 x 250 ml | P52: Oil bottle PAG100, R134, HFO1234yf, mechanical and electrical compressor, 6 x 250 ml | Q52: All A/C machines | R52: All A/C machines | S52: All A/C machines | T52: All A/C machines | U52: All A/C machines
A53: DECKAEK275-N | B53: A/C | C53: A/C | D53: A/C | E53: A/C | F53: A/C | G53: Sealed oil cartridge PAG100 - 250ml for R134a, HFO1234yf mechanical and electric compressor | H53: Hermetische Ölpatrone, PAG100, 250 ml für HFO1234yf und R134a, mechanischer und elektrischer Kompressor | I53: Sealed oil cartridge PAG100 - 250ml for R134a, HFO1234yf mechanical and electric compressor | J53: Sealed oil cartridge PAG100 - 250ml for R134a, HFO1234yf mechanical and electric compressor | K53: Sealed oil cartridge PAG100 - 250ml for R134a, HFO1234yf mechanical and electric compressor | L53: Sealed oil cartridge PAG100 - 250ml for R134a, HFO1234yf mechanical and electric compressor | M53: Hermetische Ölpatrone, PAG100, 250 ml für HFO1234yf und R134a, mechanischer und elektrischer Kompressor | N53: Sealed oil cartridge PAG100 - 250ml for R134a, HFO1234yf mechanical and electric compressor | O53: Sealed oil cartridge PAG100 - 250ml for R134a, HFO1234yf mechanical and electric compressor | P53: Sealed oil cartridge PAG100 - 250ml for R134a, HFO1234yf mechanical and electric compressor | Q53: All A/C machines | R53: All A/C machines | S53: All A/C machines | T53: All A/C machines | U53: All A/C machines
A54: DECKAEK276 | B54: A/C | C54: A/C | D54: A/C | E54: A/C | F54: A/C | G54: Oil bottle PAG46, R134, HFO1234yf, mechanical and electrical compressor, 6 x 250 ml | H54: Ölbehälter PAG45, R134, HFO1234yf, 6 x 250 ml | I54: Oil bottle PAG46, R134, HFO1234yf, mechanical and electrical compressor, 6 x 250 ml | J54: Oil bottle PAG46, R134, HFO1234yf, mechanical and electrical compressor, 6 x 250 ml | K54: Oil bottle PAG46, R134, HFO1234yf, mechanical and electrical compressor, 6 x 250 ml | L54: Oil bottle PAG46, R134, HFO1234yf, mechanical and electrical compressor, 6 x 250 ml | M54: Ölbehälter PAG45, R134, HFO1234yf, 6 x 250 ml | N54: Oil bottle PAG46, R134, HFO1234yf, mechanical and electrical compressor, 6 x 250 ml | O54: Oil bottle PAG46, R134, HFO1234yf, mechanical and electrical compressor, 6 x 250 ml | P54: Oil bottle PAG46, R134, HFO1234yf, mechanical and electrical compressor, 6 x 250 ml | Q54: All A/C machines | R54: All A/C machines | S54: All A/C machines | T54: All A/C machines | U54: All A/C machines
